Workbook

Sheet INPUT DATA
B2: SCHOOL INFORMATION | J2: LEARNERS' DATA
C5: REGION | E5: : | K5: MALE | M5: LRN | N5: BIRTHDATE | P5: FEMALE | R5: LRN | S5: BIRTHDATE
C6: DIVISION | E6: : | K6: 1 | P6: 1
C7: CITY/MUNICIPALITY | E7: : | K7: 2 | P7: 2
C8: DISTRICT | E8: : | K8: 3 | P8: 3
K9: 4 | P9: 4
C10: SCHOOL ID | E10: : | K10: 5 | P10: 5
C11: SCHOOL NAME | E11: : | K11: 6 | P11: 6
K12: 7 | P12: 7
C13: SCHOOL YEAR | E13: : | K13: 8 | P13: 8
C14: SCHOOL HEAD | E14: : | K14: 9 | P14: 9
K15: 10 | P15: 10
K16: 11 | P16: 11
K17: 12 | P17: 12
B18: TEACHER, GRADE LEVEL, SECTION INFORMATION | K18: 13 | P18: 13
K19: 14 | P19: 14
K20: 15 | P20: 15
C21: ADVISER | E21: : | K21: 16 | P21: 16
C22: GRADE LEVEL | E22: : | G22: (Accepts Grades 4 to 10 only) | K22: 17 | P22: 17
C23: SECTION | E23: : | K23: 18 | P23: 18
K24: 19 | P24: 19
C25: IMPORTANT NOTE: This is the official and final version of the file. All tabs are password-protected to prevent accidental formula edits and maintain the accuracy and integrity of the data. If you identify any inconsistencies or issues, particularly with the formulas, please report them for appropriate review and necessary correction. | K25: 20 | P25: 20
K26: 21 | P26: 21
K27: 22 | P27: 22
K28: 23 | P28: 23
K29: 24 | P29: 24
K30: 25 | P30: 25
K31: 26 | P31: 26
K32: 27 | P32: 27
K33: 28 | P33: 28
K34: 29 | P34: 29
K35: 30 | P35: 30
K36: 31 | P36: 31
K37: 32 | P37: 32
... K55: 50 | P55: 50
T57: 2026_v1.0

Sheet TERM 1
A2: FIRST TERM | E2: GRADE LEVEL | F2: =IF('INPUT DATA'!F22="","",'INPUT DATA'!F22) | K2: ADVISER | M2: =IF('INPUT DATA'!F21="","",'INPUT DATA'!F21)
E3: SECTION | F3: =IF('INPUT DATA'!F23="","",'INPUT DATA'!F23)
A4: LEARNERS' NAMES | E4: LRN | G4: Date of Birth | H4: Age | I4: Sex | J4: Learning Areas | T4: Final Grade | U4: Rank
J5: Filipino | K5: English | L5: Mathematics | M5: Science | N5: AP | O5: GMRC/VE | P5: EPP/TLE | Q5: MAPEH
Q6: M A | R6: P E H | S6: Term Grade
A7: MALE
A8: 1 | B8: =IF('INPUT DATA'!L6="","",'INPUT DATA'!L6) | E8: =IF('INPUT DATA'!M6="","",'INPUT DATA'!M6) | G8: =IF('INPUT DATA'!N6="","",'INPUT DATA'!N6) | H8: =IF(G8="","",DATEDIF(G8,TODAY(),"Y")) | I8: =IF(B8="","","M") | S8: =IF(COUNT($Q8:$R8)=0,"",ROUND(AVERAGE(Q8:R8),0)) | T8: =IF(COUNT(J8:P8,S8)=0,"",ROUND(AVERAGE(J8:P8,S8),0)) | U8: =IF(T8="","",_xlfn.RANK.AVG(T8,$T$8:$T$108))
A9: 2 | B9: =IF('INPUT DATA'!L7="","",'INPUT DATA'!L7) | E9: =IF('INPUT DATA'!M7="","",'INPUT DATA'!M7) | G9: =IF('INPUT DATA'!N7="","",'INPUT DATA'!N7) | H9: =IF(G9="","",DATEDIF(G9,TODAY(),"Y")) | I9: =IF(B9="","","M") | S9: =IF(COUNT($Q9:$R9)=0,"",ROUND(AVERAGE(Q9:R9),0)) | T9: =IF(COUNT(J9:P9,S9)=0,"",ROUND(AVERAGE(J9:P9,S9),0)) | U9: =IF(T9="","",_xlfn.RANK.AVG(T9,$T$8:$T$108))
A10: 3 | B10: =IF('INPUT DATA'!L8="","",'INPUT DATA'!L8) | E10: =IF('INPUT DATA'!M8="","",'INPUT DATA'!M8) | G10: =IF('INPUT DATA'!N8="","",'INPUT DATA'!N8) | H10: =IF(G10="","",DATEDIF(G10,TODAY(),"Y")) | I10: =IF(B10="","","M") | S10: =IF(COUNT($Q10:$R10)=0,"",ROUND(AVERAGE(Q10:R10),0)) | T10: =IF(COUNT(J10:P10,S10)=0,"",ROUND(AVERAGE(J10:P10,S10),0)) | U10: =IF(T10="","",_xlfn.RANK.AVG(T10,$T$8:$T$108))
A11: 4 | B11: =IF('INPUT DATA'!L9="","",'INPUT DATA'!L9) | E11: =IF('INPUT DATA'!M9="","",'INPUT DATA'!M9) | G11: =IF('INPUT DATA'!N9="","",'INPUT DATA'!N9) | H11: =IF(G11="","",DATEDIF(G11,TODAY(),"Y")) | I11: =IF(B11="","","M") | S11: =IF(COUNT($Q11:$R11)=0,"",ROUND(AVERAGE(Q11:R11),0)) | T11: =IF(COUNT(J11:P11,S11)=0,"",ROUND(AVERAGE(J11:P11,S11),0)) | U11: =IF(T11="","",_xlfn.RANK.AVG(T11,$T$8:$T$108))
A12: 5 | B12: =IF('INPUT DATA'!L10="","",'INPUT DATA'!L10) | E12: =IF('INPUT DATA'!M10="","",'INPUT DATA'!M10) | G12: =IF('INPUT DATA'!N10="","",'INPUT DATA'!N10) | H12: =IF(G12="","",DATEDIF(G12,TODAY(),"Y")) | I12: =IF(B12="","","M") | S12: =IF(COUNT($Q12:$R12)=0,"",ROUND(AVERAGE(Q12:R12),0)) | T12: =IF(COUNT(J12:P12,S12)=0,"",ROUND(AVERAGE(J12:P12,S12),0)) | U12: =IF(T12="","",_xlfn.RANK.AVG(T12,$T$8:$T$108))
A13: 6 | B13: =IF('INPUT DATA'!L11="","",'INPUT DATA'!L11) | E13: =IF('INPUT DATA'!M11="","",'INPUT DATA'!M11) | G13: =IF('INPUT DATA'!N11="","",'INPUT DATA'!N11) | H13: =IF(G13="","",DATEDIF(G13,TODAY(),"Y")) | I13: =IF(B13="","","M") | S13: =IF(COUNT($Q13:$R13)=0,"",ROUND(AVERAGE(Q13:R13),0)) | T13: =IF(COUNT(J13:P13,S13)=0,"",ROUND(AVERAGE(J13:P13,S13),0)) | U13: =IF(T13="","",_xlfn.RANK.AVG(T13,$T$8:$T$108))
A14: 7 | B14: =IF('INPUT DATA'!L12="","",'INPUT DATA'!L12) | E14: =IF('INPUT DATA'!M12="","",'INPUT DATA'!M12) | G14: =IF('INPUT DATA'!N12="","",'INPUT DATA'!N12) | H14: =IF(G14="","",DATEDIF(G14,TODAY(),"Y")) | I14: =IF(B14="","","M") | S14: =IF(COUNT($Q14:$R14)=0,"",ROUND(AVERAGE(Q14:R14),0)) | T14: =IF(COUNT(J14:P14,S14)=0,"",ROUND(AVERAGE(J14:P14,S14),0)) | U14: =IF(T14="","",_xlfn.RANK.AVG(T14,$T$8:$T$108))
A15: 8 | B15: =IF('INPUT DATA'!L13="","",'INPUT DATA'!L13) | E15: =IF('INPUT DATA'!M13="","",'INPUT DATA'!M13) | G15: =IF('INPUT DATA'!N13="","",'INPUT DATA'!N13) | H15: =IF(G15="","",DATEDIF(G15,TODAY(),"Y")) | I15: =IF(B15="","","M") | S15: =IF(COUNT($Q15:$R15)=0,"",ROUND(AVERAGE(Q15:R15),0)) | T15: =IF(COUNT(J15:P15,S15)=0,"",ROUND(AVERAGE(J15:P15,S15),0)) | U15: =IF(T15="","",_xlfn.RANK.AVG(T15,$T$8:$T$108))
A16: 9 | B16: =IF('INPUT DATA'!L14="","",'INPUT DATA'!L14) | E16: =IF('INPUT DATA'!M14="","",'INPUT DATA'!M14) | G16: =IF('INPUT DATA'!N14="","",'INPUT DATA'!N14) | H16: =IF(G16="","",DATEDIF(G16,TODAY(),"Y")) | I16: =IF(B16="","","M") | S16: =IF(COUNT($Q16:$R16)=0,"",ROUND(AVERAGE(Q16:R16),0)) | T16: =IF(COUNT(J16:P16,S16)=0,"",ROUND(AVERAGE(J16:P16,S16),0)) | U16: =IF(T16="","",_xlfn.RANK.AVG(T16,$T$8:$T$108))
A17: 10 | B17: =IF('INPUT DATA'!L15="","",'INPUT DATA'!L15) | E17: =IF('INPUT DATA'!M15="","",'INPUT DATA'!M15) | G17: =IF('INPUT DATA'!N15="","",'INPUT DATA'!N15) | H17: =IF(G17="","",DATEDIF(G17,TODAY(),"Y")) | I17: =IF(B17="","","M") | S17: =IF(COUNT($Q17:$R17)=0,"",ROUND(AVERAGE(Q17:R17),0)) | T17: =IF(COUNT(J17:P17,S17)=0,"",ROUND(AVERAGE(J17:P17,S17),0)) | U17: =IF(T17="","",_xlfn.RANK.AVG(T17,$T$8:$T$108))
A18: 11 | B18: =IF('INPUT DATA'!L16="","",'INPUT DATA'!L16) | E18: =IF('INPUT DATA'!M16="","",'INPUT DATA'!M16) | G18: =IF('INPUT DATA'!N16="","",'INPUT DATA'!N16) | H18: =IF(G18="","",DATEDIF(G18,TODAY(),"Y")) | I18: =IF(B18="","","M") | S18: =IF(COUNT($Q18:$R18)=0,"",ROUND(AVERAGE(Q18:R18),0)) | T18: =IF(COUNT(J18:P18,S18)=0,"",ROUND(AVERAGE(J18:P18,S18),0)) | U18: =IF(T18="","",_xlfn.RANK.AVG(T18,$T$8:$T$108))
A19: 12 | B19: =IF('INPUT DATA'!L17="","",'INPUT DATA'!L17) | E19: =IF('INPUT DATA'!M17="","",'INPUT DATA'!M17) | G19: =IF('INPUT DATA'!N17="","",'INPUT DATA'!N17) | H19: =IF(G19="","",DATEDIF(G19,TODAY(),"Y")) | I19: =IF(B19="","","M") | S19: =IF(COUNT($Q19:$R19)=0,"",ROUND(AVERAGE(Q19:R19),0)) | T19: =IF(COUNT(J19:P19,S19)=0,"",ROUND(AVERAGE(J19:P19,S19),0)) | U19: =IF(T19="","",_xlfn.RANK.AVG(T19,$T$8:$T$108))
... A57: 50 | B57: =IF('INPUT DATA'!L55="","",'INPUT DATA'!L55) | E57: =IF('INPUT DATA'!M55="","",'INPUT DATA'!M55) | G57: =IF('INPUT DATA'!N55="","",'INPUT DATA'!N55) | H57: =IF(G57="","",DATEDIF(G57,TODAY(),"Y")) | I57: =IF(B57="","","M") | S57: =IF(COUNT($Q57:$R57)=0,"",ROUND(AVERAGE(Q57:R57),0)) | T57: =IF(COUNT(J57:P57,S57)=0,"",ROUND(AVERAGE(J57:P57,S57),0)) | U57: =IF(T57="","",_xlfn.RANK.AVG(T57,$T$8:$T$108))
A58: FEMALE
A59: 1 | B59: =IF('INPUT DATA'!Q6="","",'INPUT DATA'!Q6) | E59: =IF('INPUT DATA'!R6="","",'INPUT DATA'!R6) | G59: =IF('INPUT DATA'!S6="","",'INPUT DATA'!S6) | H59: =IF(G59="","",DATEDIF(G59,TODAY(),"Y")) | I59: =IF(B59="","","F") | S59: =IF(COUNT($Q59:$R59)=0,"",ROUND(AVERAGE(Q59:R59),0)) | T59: =IF(COUNT(J59:P59,S59)=0,"",ROUND(AVERAGE(J59:P59,S59),0)) | U59: =IF(T59="","",_xlfn.RANK.AVG(T59,$T$8:$T$108))
A60: 2 | B60: =IF('INPUT DATA'!Q7="","",'INPUT DATA'!Q7) | E60: =IF('INPUT DATA'!R7="","",'INPUT DATA'!R7) | G60: =IF('INPUT DATA'!S7="","",'INPUT DATA'!S7) | H60: =IF(G60="","",DATEDIF(G60,TODAY(),"Y")) | I60: =IF(B60="","","F") | S60: =IF(COUNT($Q60:$R60)=0,"",ROUND(AVERAGE(Q60:R60),0)) | T60: =IF(COUNT(J60:P60,S60)=0,"",ROUND(AVERAGE(J60:P60,S60),0)) | U60: =IF(T60="","",_xlfn.RANK.AVG(T60,$T$8:$T$108))
A61: 3 | B61: =IF('INPUT DATA'!Q8="","",'INPUT DATA'!Q8) | E61: =IF('INPUT DATA'!R8="","",'INPUT DATA'!R8) | G61: =IF('INPUT DATA'!S8="","",'INPUT DATA'!S8) | H61: =IF(G61="","",DATEDIF(G61,TODAY(),"Y")) | I61: =IF(B61="","","F") | S61: =IF(COUNT($Q61:$R61)=0,"",ROUND(AVERAGE(Q61:R61),0)) | T61: =IF(COUNT(J61:P61,S61)=0,"",ROUND(AVERAGE(J61:P61,S61),0)) | U61: =IF(T61="","",_xlfn.RANK.AVG(T61,$T$8:$T$108))
A62: 4 | B62: =IF('INPUT DATA'!Q9="","",'INPUT DATA'!Q9) | E62: =IF('INPUT DATA'!R9="","",'INPUT DATA'!R9) | G62: =IF('INPUT DATA'!S9="","",'INPUT DATA'!S9) | H62: =IF(G62="","",DATEDIF(G62,TODAY(),"Y")) | I62: =IF(B62="","","F") | S62: =IF(COUNT($Q62:$R62)=0,"",ROUND(AVERAGE(Q62:R62),0)) | T62: =IF(COUNT(J62:P62,S62)=0,"",ROUND(AVERAGE(J62:P62,S62),0)) | U62: =IF(T62="","",_xlfn.RANK.AVG(T62,$T$8:$T$108))
A63: 5 | B63: =IF('INPUT DATA'!Q10="","",'INPUT DATA'!Q10) | E63: =IF('INPUT DATA'!R10="","",'INPUT DATA'!R10) | G63: =IF('INPUT DATA'!S10="","",'INPUT DATA'!S10) | H63: =IF(G63="","",DATEDIF(G63,TODAY(),"Y")) | I63: =IF(B63="","","F") | S63: =IF(COUNT($Q63:$R63)=0,"",ROUND(AVERAGE(Q63:R63),0)) | T63: =IF(COUNT(J63:P63,S63)=0,"",ROUND(AVERAGE(J63:P63,S63),0)) | U63: =IF(T63="","",_xlfn.RANK.AVG(T63,$T$8:$T$108))
A64: 6 | B64: =IF('INPUT DATA'!Q11="","",'INPUT DATA'!Q11) | E64: =IF('INPUT DATA'!R11="","",'INPUT DATA'!R11) | G64: =IF('INPUT DATA'!S11="","",'INPUT DATA'!S11) | H64: =IF(G64="","",DATEDIF(G64,TODAY(),"Y")) | I64: =IF(B64="","","F") | S64: =IF(COUNT($Q64:$R64)=0,"",ROUND(AVERAGE(Q64:R64),0)) | T64: =IF(COUNT(J64:P64,S64)=0,"",ROUND(AVERAGE(J64:P64,S64),0)) | U64: =IF(T64="","",_xlfn.RANK.AVG(T64,$T$8:$T$108))
A65: 7 | B65: =IF('INPUT DATA'!Q12="","",'INPUT DATA'!Q12) | E65: =IF('INPUT DATA'!R12="","",'INPUT DATA'!R12) | G65: =IF('INPUT DATA'!S12="","",'INPUT DATA'!S12) | H65: =IF(G65="","",DATEDIF(G65,TODAY(),"Y")) | I65: =IF(B65="","","F") | S65: =IF(COUNT($Q65:$R65)=0,"",ROUND(AVERAGE(Q65:R65),0)) | T65: =IF(COUNT(J65:P65,S65)=0,"",ROUND(AVERAGE(J65:P65,S65),0)) | U65: =IF(T65="","",_xlfn.RANK.AVG(T65,$T$8:$T$108))
A66: 8 | B66: =IF('INPUT DATA'!Q13="","",'INPUT DATA'!Q13) | E66: =IF('INPUT DATA'!R13="","",'INPUT DATA'!R13) | G66: =IF('INPUT DATA'!S13="","",'INPUT DATA'!S13) | H66: =IF(G66="","",DATEDIF(G66,TODAY(),"Y")) | I66: =IF(B66="","","F") | S66: =IF(COUNT($Q66:$R66)=0,"",ROUND(AVERAGE(Q66:R66),0)) | T66: =IF(COUNT(J66:P66,S66)=0,"",ROUND(AVERAGE(J66:P66,S66),0)) | U66: =IF(T66="","",_xlfn.RANK.AVG(T66,$T$8:$T$108))
A67: 9 | B67: =IF('INPUT DATA'!Q14="","",'INPUT DATA'!Q14) | E67: =IF('INPUT DATA'!R14="","",'INPUT DATA'!R14) | G67: =IF('INPUT DATA'!S14="","",'INPUT DATA'!S14) | H67: =IF(G67="","",DATEDIF(G67,TODAY(),"Y")) | I67: =IF(B67="","","F") | S67: =IF(COUNT($Q67:$R67)=0,"",ROUND(AVERAGE(Q67:R67),0)) | T67: =IF(COUNT(J67:P67,S67)=0,"",ROUND(AVERAGE(J67:P67,S67),0)) | U67: =IF(T67="","",_xlfn.RANK.AVG(T67,$T$8:$T$108))
A68: 10 | B68: =IF('INPUT DATA'!Q15="","",'INPUT DATA'!Q15) | E68: =IF('INPUT DATA'!R15="","",'INPUT DATA'!R15) | G68: =IF('INPUT DATA'!S15="","",'INPUT DATA'!S15) | H68: =IF(G68="","",DATEDIF(G68,TODAY(),"Y")) | I68: =IF(B68="","","F") | S68: =IF(COUNT($Q68:$R68)=0,"",ROUND(AVERAGE(Q68:R68),0)) | T68: =IF(COUNT(J68:P68,S68)=0,"",ROUND(AVERAGE(J68:P68,S68),0)) | U68: =IF(T68="","",_xlfn.RANK.AVG(T68,$T$8:$T$108))
A69: 11 | B69: =IF('INPUT DATA'!Q16="","",'INPUT DATA'!Q16) | E69: =IF('INPUT DATA'!R16="","",'INPUT DATA'!R16) | G69: =IF('INPUT DATA'!S16="","",'INPUT DATA'!S16) | H69: =IF(G69="","",DATEDIF(G69,TODAY(),"Y")) | I69: =IF(B69="","","F") | S69: =IF(COUNT($Q69:$R69)=0,"",ROUND(AVERAGE(Q69:R69),0)) | T69: =IF(COUNT(J69:P69,S69)=0,"",ROUND(AVERAGE(J69:P69,S69),0)) | U69: =IF(T69="","",_xlfn.RANK.AVG(T69,$T$8:$T$108))
A70: 12 | B70: =IF('INPUT DATA'!Q17="","",'INPUT DATA'!Q17) | E70: =IF('INPUT DATA'!R17="","",'INPUT DATA'!R17) | G70: =IF('INPUT DATA'!S17="","",'INPUT DATA'!S17) | H70: =IF(G70="","",DATEDIF(G70,TODAY(),"Y")) | I70: =IF(B70="","","F") | S70: =IF(COUNT($Q70:$R70)=0,"",ROUND(AVERAGE(Q70:R70),0)) | T70: =IF(COUNT(J70:P70,S70)=0,"",ROUND(AVERAGE(J70:P70,S70),0)) | U70: =IF(T70="","",_xlfn.RANK.AVG(T70,$T$8:$T$108))
... A108: 50 | B108: =IF('INPUT DATA'!Q55="","",'INPUT DATA'!Q55) | E108: =IF('INPUT DATA'!R55="","",'INPUT DATA'!R55) | G108: =IF('INPUT DATA'!S55="","",'INPUT DATA'!S55) | H108: =IF(G108="","",DATEDIF(G108,TODAY(),"Y")) | I108: =IF(B108="","","F") | S108: =IF(COUNT($Q108:$R108)=0,"",ROUND(AVERAGE(Q108:R108),0)) | T108: =IF(COUNT(J108:P108,S108)=0,"",ROUND(AVERAGE(J108:P108,S108),0)) | U108: =IF(T108="","",_xlfn.RANK.AVG(T108,$T$8:$T$108))

Sheet TERM 2
A2: SECOND TERM | E2: GRADE LEVEL | F2: =IF('INPUT DATA'!F22="","",'INPUT DATA'!F22) | K2: ADVISER | M2: =IF('INPUT DATA'!F21="","",'INPUT DATA'!F21)
E3: SECTION | F3: =IF('INPUT DATA'!F23="","",'INPUT DATA'!F23)
A4: LEARNERS' NAMES | E4: LRN | G4: Date of Birth | H4: Age | I4: Sex | J4: Learning Areas | T4: Final Grade | U4: Rank
J5: Filipino | K5: English | L5: Mathematics | M5: Science | N5: AP | O5: GMRC/VE | P5: EPP/TLE | Q5: MAPEH
Q6: M A | R6: P E H | S6: Term Grade
A7: MALE
A8: 1 | B8: =IF('INPUT DATA'!L6="","",'INPUT DATA'!L6) | E8: =IF('INPUT DATA'!M6="","",'INPUT DATA'!M6) | G8: =IF('INPUT DATA'!N6="","",'INPUT DATA'!N6) | H8: =IF(G8="","",DATEDIF(G8,TODAY(),"Y")) | I8: =IF(B8="","","M") | S8: =IF(COUNT($Q8:$R8)=0,"",ROUND(AVERAGE(Q8:R8),0)) | T8: =IF(COUNT(J8:P8,S8)=0,"",ROUND(AVERAGE(J8:P8,S8),0)) | U8: =IF(T8="","",_xlfn.RANK.AVG(T8,$T$8:$T$108))
A9: 2 | B9: =IF('INPUT DATA'!L7="","",'INPUT DATA'!L7) | E9: =IF('INPUT DATA'!M7="","",'INPUT DATA'!M7) | G9: =IF('INPUT DATA'!N7="","",'INPUT DATA'!N7) | H9: =IF(G9="","",DATEDIF(G9,TODAY(),"Y")) | I9: =IF(B9="","","M") | S9: =IF(COUNT($Q9:$R9)=0,"",ROUND(AVERAGE(Q9:R9),0)) | T9: =IF(COUNT(J9:P9,S9)=0,"",ROUND(AVERAGE(J9:P9,S9),0)) | U9: =IF(T9="","",_xlfn.RANK.AVG(T9,$T$8:$T$108))
A10: 3 | B10: =IF('INPUT DATA'!L8="","",'INPUT DATA'!L8) | E10: =IF('INPUT DATA'!M8="","",'INPUT DATA'!M8) | G10: =IF('INPUT DATA'!N8="","",'INPUT DATA'!N8) | H10: =IF(G10="","",DATEDIF(G10,TODAY(),"Y")) | I10: =IF(B10="","","M") | S10: =IF(COUNT($Q10:$R10)=0,"",ROUND(AVERAGE(Q10:R10),0)) | T10: =IF(COUNT(J10:P10,S10)=0,"",ROUND(AVERAGE(J10:P10,S10),0)) | U10: =IF(T10="","",_xlfn.RANK.AVG(T10,$T$8:$T$108))
A11: 4 | B11: =IF('INPUT DATA'!L9="","",'INPUT DATA'!L9) | E11: =IF('INPUT DATA'!M9="","",'INPUT DATA'!M9) | G11: =IF('INPUT DATA'!N9="","",'INPUT DATA'!N9) | H11: =IF(G11="","",DATEDIF(G11,TODAY(),"Y")) | I11: =IF(B11="","","M") | S11: =IF(COUNT($Q11:$R11)=0,"",ROUND(AVERAGE(Q11:R11),0)) | T11: =IF(COUNT(J11:P11,S11)=0,"",ROUND(AVERAGE(J11:P11,S11),0)) | U11: =IF(T11="","",_xlfn.RANK.AVG(T11,$T$8:$T$108))
A12: 5 | B12: =IF('INPUT DATA'!L10="","",'INPUT DATA'!L10) | E12: =IF('INPUT DATA'!M10="","",'INPUT DATA'!M10) | G12: =IF('INPUT DATA'!N10="","",'INPUT DATA'!N10) | H12: =IF(G12="","",DATEDIF(G12,TODAY(),"Y")) | I12: =IF(B12="","","M") | S12: =IF(COUNT($Q12:$R12)=0,"",ROUND(AVERAGE(Q12:R12),0)) | T12: =IF(COUNT(J12:P12,S12)=0,"",ROUND(AVERAGE(J12:P12,S12),0)) | U12: =IF(T12="","",_xlfn.RANK.AVG(T12,$T$8:$T$108))
A13: 6 | B13: =IF('INPUT DATA'!L11="","",'INPUT DATA'!L11) | E13: =IF('INPUT DATA'!M11="","",'INPUT DATA'!M11) | G13: =IF('INPUT DATA'!N11="","",'INPUT DATA'!N11) | H13: =IF(G13="","",DATEDIF(G13,TODAY(),"Y")) | I13: =IF(B13="","","M") | S13: =IF(COUNT($Q13:$R13)=0,"",ROUND(AVERAGE(Q13:R13),0)) | T13: =IF(COUNT(J13:P13,S13)=0,"",ROUND(AVERAGE(J13:P13,S13),0)) | U13: =IF(T13="","",_xlfn.RANK.AVG(T13,$T$8:$T$108))
A14: 7 | B14: =IF('INPUT DATA'!L12="","",'INPUT DATA'!L12) | E14: =IF('INPUT DATA'!M12="","",'INPUT DATA'!M12) | G14: =IF('INPUT DATA'!N12="","",'INPUT DATA'!N12) | H14: =IF(G14="","",DATEDIF(G14,TODAY(),"Y")) | I14: =IF(B14="","","M") | S14: =IF(COUNT($Q14:$R14)=0,"",ROUND(AVERAGE(Q14:R14),0)) | T14: =IF(COUNT(J14:P14,S14)=0,"",ROUND(AVERAGE(J14:P14,S14),0)) | U14: =IF(T14="","",_xlfn.RANK.AVG(T14,$T$8:$T$108))
A15: 8 | B15: =IF('INPUT DATA'!L13="","",'INPUT DATA'!L13) | E15: =IF('INPUT DATA'!M13="","",'INPUT DATA'!M13) | G15: =IF('INPUT DATA'!N13="","",'INPUT DATA'!N13) | H15: =IF(G15="","",DATEDIF(G15,TODAY(),"Y")) | I15: =IF(B15="","","M") | S15: =IF(COUNT($Q15:$R15)=0,"",ROUND(AVERAGE(Q15:R15),0)) | T15: =IF(COUNT(J15:P15,S15)=0,"",ROUND(AVERAGE(J15:P15,S15),0)) | U15: =IF(T15="","",_xlfn.RANK.AVG(T15,$T$8:$T$108))
A16: 9 | B16: =IF('INPUT DATA'!L14="","",'INPUT DATA'!L14) | E16: =IF('INPUT DATA'!M14="","",'INPUT DATA'!M14) | G16: =IF('INPUT DATA'!N14="","",'INPUT DATA'!N14) | H16: =IF(G16="","",DATEDIF(G16,TODAY(),"Y")) | I16: =IF(B16="","","M") | S16: =IF(COUNT($Q16:$R16)=0,"",ROUND(AVERAGE(Q16:R16),0)) | T16: =IF(COUNT(J16:P16,S16)=0,"",ROUND(AVERAGE(J16:P16,S16),0)) | U16: =IF(T16="","",_xlfn.RANK.AVG(T16,$T$8:$T$108))
A17: 10 | B17: =IF('INPUT DATA'!L15="","",'INPUT DATA'!L15) | E17: =IF('INPUT DATA'!M15="","",'INPUT DATA'!M15) | G17: =IF('INPUT DATA'!N15="","",'INPUT DATA'!N15) | H17: =IF(G17="","",DATEDIF(G17,TODAY(),"Y")) | I17: =IF(B17="","","M") | S17: =IF(COUNT($Q17:$R17)=0,"",ROUND(AVERAGE(Q17:R17),0)) | T17: =IF(COUNT(J17:P17,S17)=0,"",ROUND(AVERAGE(J17:P17,S17),0)) | U17: =IF(T17="","",_xlfn.RANK.AVG(T17,$T$8:$T$108))
A18: 11 | B18: =IF('INPUT DATA'!L16="","",'INPUT DATA'!L16) | E18: =IF('INPUT DATA'!M16="","",'INPUT DATA'!M16) | G18: =IF('INPUT DATA'!N16="","",'INPUT DATA'!N16) | H18: =IF(G18="","",DATEDIF(G18,TODAY(),"Y")) | I18: =IF(B18="","","M") | S18: =IF(COUNT($Q18:$R18)=0,"",ROUND(AVERAGE(Q18:R18),0)) | T18: =IF(COUNT(J18:P18,S18)=0,"",ROUND(AVERAGE(J18:P18,S18),0)) | U18: =IF(T18="","",_xlfn.RANK.AVG(T18,$T$8:$T$108))
A19: 12 | B19: =IF('INPUT DATA'!L17="","",'INPUT DATA'!L17) | E19: =IF('INPUT DATA'!M17="","",'INPUT DATA'!M17) | G19: =IF('INPUT DATA'!N17="","",'INPUT DATA'!N17) | H19: =IF(G19="","",DATEDIF(G19,TODAY(),"Y")) | I19: =IF(B19="","","M") | S19: =IF(COUNT($Q19:$R19)=0,"",ROUND(AVERAGE(Q19:R19),0)) | T19: =IF(COUNT(J19:P19,S19)=0,"",ROUND(AVERAGE(J19:P19,S19),0)) | U19: =IF(T19="","",_xlfn.RANK.AVG(T19,$T$8:$T$108))
... A57: 50 | B57: =IF('INPUT DATA'!L55="","",'INPUT DATA'!L55) | E57: =IF('INPUT DATA'!M55="","",'INPUT DATA'!M55) | G57: =IF('INPUT DATA'!N55="","",'INPUT DATA'!N55) | H57: =IF(G57="","",DATEDIF(G57,TODAY(),"Y")) | I57: =IF(B57="","","M") | S57: =IF(COUNT($Q57:$R57)=0,"",ROUND(AVERAGE(Q57:R57),0)) | T57: =IF(COUNT(J57:P57,S57)=0,"",ROUND(AVERAGE(J57:P57,S57),0)) | U57: =IF(T57="","",_xlfn.RANK.AVG(T57,$T$8:$T$108))
A58: FEMALE
A59: 1 | B59: =IF('INPUT DATA'!Q6="","",'INPUT DATA'!Q6) | E59: =IF('INPUT DATA'!R6="","",'INPUT DATA'!R6) | G59: =IF('INPUT DATA'!S6="","",'INPUT DATA'!S6) | H59: =IF(G59="","",DATEDIF(G59,TODAY(),"Y")) | I59: =IF(B59="","","F") | S59: =IF(COUNT($Q59:$R59)=0,"",ROUND(AVERAGE(Q59:R59),0)) | T59: =IF(COUNT(J59:P59,S59)=0,"",ROUND(AVERAGE(J59:P59,S59),0)) | U59: =IF(T59="","",_xlfn.RANK.AVG(T59,$T$8:$T$108))
A60: 2 | B60: =IF('INPUT DATA'!Q7="","",'INPUT DATA'!Q7) | E60: =IF('INPUT DATA'!R7="","",'INPUT DATA'!R7) | G60: =IF('INPUT DATA'!S7="","",'INPUT DATA'!S7) | H60: =IF(G60="","",DATEDIF(G60,TODAY(),"Y")) | I60: =IF(B60="","","F") | S60: =IF(COUNT($Q60:$R60)=0,"",ROUND(AVERAGE(Q60:R60),0)) | T60: =IF(COUNT(J60:P60,S60)=0,"",ROUND(AVERAGE(J60:P60,S60),0)) | U60: =IF(T60="","",_xlfn.RANK.AVG(T60,$T$8:$T$108))
A61: 3 | B61: =IF('INPUT DATA'!Q8="","",'INPUT DATA'!Q8) | E61: =IF('INPUT DATA'!R8="","",'INPUT DATA'!R8) | G61: =IF('INPUT DATA'!S8="","",'INPUT DATA'!S8) | H61: =IF(G61="","",DATEDIF(G61,TODAY(),"Y")) | I61: =IF(B61="","","F") | S61: =IF(COUNT($Q61:$R61)=0,"",ROUND(AVERAGE(Q61:R61),0)) | T61: =IF(COUNT(J61:P61,S61)=0,"",ROUND(AVERAGE(J61:P61,S61),0)) | U61: =IF(T61="","",_xlfn.RANK.AVG(T61,$T$8:$T$108))
A62: 4 | B62: =IF('INPUT DATA'!Q9="","",'INPUT DATA'!Q9) | E62: =IF('INPUT DATA'!R9="","",'INPUT DATA'!R9) | G62: =IF('INPUT DATA'!S9="","",'INPUT DATA'!S9) | H62: =IF(G62="","",DATEDIF(G62,TODAY(),"Y")) | I62: =IF(B62="","","F") | S62: =IF(COUNT($Q62:$R62)=0,"",ROUND(AVERAGE(Q62:R62),0)) | T62: =IF(COUNT(J62:P62,S62)=0,"",ROUND(AVERAGE(J62:P62,S62),0)) | U62: =IF(T62="","",_xlfn.RANK.AVG(T62,$T$8:$T$108))
A63: 5 | B63: =IF('INPUT DATA'!Q10="","",'INPUT DATA'!Q10) | E63: =IF('INPUT DATA'!R10="","",'INPUT DATA'!R10) | G63: =IF('INPUT DATA'!S10="","",'INPUT DATA'!S10) | H63: =IF(G63="","",DATEDIF(G63,TODAY(),"Y")) | I63: =IF(B63="","","F") | S63: =IF(COUNT($Q63:$R63)=0,"",ROUND(AVERAGE(Q63:R63),0)) | T63: =IF(COUNT(J63:P63,S63)=0,"",ROUND(AVERAGE(J63:P63,S63),0)) | U63: =IF(T63="","",_xlfn.RANK.AVG(T63,$T$8:$T$108))
A64: 6 | B64: =IF('INPUT DATA'!Q11="","",'INPUT DATA'!Q11) | E64: =IF('INPUT DATA'!R11="","",'INPUT DATA'!R11) | G64: =IF('INPUT DATA'!S11="","",'INPUT DATA'!S11) | H64: =IF(G64="","",DATEDIF(G64,TODAY(),"Y")) | I64: =IF(B64="","","F") | S64: =IF(COUNT($Q64:$R64)=0,"",ROUND(AVERAGE(Q64:R64),0)) | T64: =IF(COUNT(J64:P64,S64)=0,"",ROUND(AVERAGE(J64:P64,S64),0)) | U64: =IF(T64="","",_xlfn.RANK.AVG(T64,$T$8:$T$108))
A65: 7 | B65: =IF('INPUT DATA'!Q12="","",'INPUT DATA'!Q12) | E65: =IF('INPUT DATA'!R12="","",'INPUT DATA'!R12) | G65: =IF('INPUT DATA'!S12="","",'INPUT DATA'!S12) | H65: =IF(G65="","",DATEDIF(G65,TODAY(),"Y")) | I65: =IF(B65="","","F") | S65: =IF(COUNT($Q65:$R65)=0,"",ROUND(AVERAGE(Q65:R65),0)) | T65: =IF(COUNT(J65:P65,S65)=0,"",ROUND(AVERAGE(J65:P65,S65),0)) | U65: =IF(T65="","",_xlfn.RANK.AVG(T65,$T$8:$T$108))
A66: 8 | B66: =IF('INPUT DATA'!Q13="","",'INPUT DATA'!Q13) | E66: =IF('INPUT DATA'!R13="","",'INPUT DATA'!R13) | G66: =IF('INPUT DATA'!S13="","",'INPUT DATA'!S13) | H66: =IF(G66="","",DATEDIF(G66,TODAY(),"Y")) | I66: =IF(B66="","","F") | S66: =IF(COUNT($Q66:$R66)=0,"",ROUND(AVERAGE(Q66:R66),0)) | T66: =IF(COUNT(J66:P66,S66)=0,"",ROUND(AVERAGE(J66:P66,S66),0)) | U66: =IF(T66="","",_xlfn.RANK.AVG(T66,$T$8:$T$108))
A67: 9 | B67: =IF('INPUT DATA'!Q14="","",'INPUT DATA'!Q14) | E67: =IF('INPUT DATA'!R14="","",'INPUT DATA'!R14) | G67: =IF('INPUT DATA'!S14="","",'INPUT DATA'!S14) | H67: =IF(G67="","",DATEDIF(G67,TODAY(),"Y")) | I67: =IF(B67="","","F") | S67: =IF(COUNT($Q67:$R67)=0,"",ROUND(AVERAGE(Q67:R67),0)) | T67: =IF(COUNT(J67:P67,S67)=0,"",ROUND(AVERAGE(J67:P67,S67),0)) | U67: =IF(T67="","",_xlfn.RANK.AVG(T67,$T$8:$T$108))
A68: 10 | B68: =IF('INPUT DATA'!Q15="","",'INPUT DATA'!Q15) | E68: =IF('INPUT DATA'!R15="","",'INPUT DATA'!R15) | G68: =IF('INPUT DATA'!S15="","",'INPUT DATA'!S15) | H68: =IF(G68="","",DATEDIF(G68,TODAY(),"Y")) | I68: =IF(B68="","","F") | S68: =IF(COUNT($Q68:$R68)=0,"",ROUND(AVERAGE(Q68:R68),0)) | T68: =IF(COUNT(J68:P68,S68)=0,"",ROUND(AVERAGE(J68:P68,S68),0)) | U68: =IF(T68="","",_xlfn.RANK.AVG(T68,$T$8:$T$108))
A69: 11 | B69: =IF('INPUT DATA'!Q16="","",'INPUT DATA'!Q16) | E69: =IF('INPUT DATA'!R16="","",'INPUT DATA'!R16) | G69: =IF('INPUT DATA'!S16="","",'INPUT DATA'!S16) | H69: =IF(G69="","",DATEDIF(G69,TODAY(),"Y")) | I69: =IF(B69="","","F") | S69: =IF(COUNT($Q69:$R69)=0,"",ROUND(AVERAGE(Q69:R69),0)) | T69: =IF(COUNT(J69:P69,S69)=0,"",ROUND(AVERAGE(J69:P69,S69),0)) | U69: =IF(T69="","",_xlfn.RANK.AVG(T69,$T$8:$T$108))
A70: 12 | B70: =IF('INPUT DATA'!Q17="","",'INPUT DATA'!Q17) | E70: =IF('INPUT DATA'!R17="","",'INPUT DATA'!R17) | G70: =IF('INPUT DATA'!S17="","",'INPUT DATA'!S17) | H70: =IF(G70="","",DATEDIF(G70,TODAY(),"Y")) | I70: =IF(B70="","","F") | S70: =IF(COUNT($Q70:$R70)=0,"",ROUND(AVERAGE(Q70:R70),0)) | T70: =IF(COUNT(J70:P70,S70)=0,"",ROUND(AVERAGE(J70:P70,S70),0)) | U70: =IF(T70="","",_xlfn.RANK.AVG(T70,$T$8:$T$108))
... A108: 50 | B108: =IF('INPUT DATA'!Q55="","",'INPUT DATA'!Q55) | E108: =IF('INPUT DATA'!R55="","",'INPUT DATA'!R55) | G108: =IF('INPUT DATA'!S55="","",'INPUT DATA'!S55) | H108: =IF(G108="","",DATEDIF(G108,TODAY(),"Y")) | I108: =IF(B108="","","F") | S108: =IF(COUNT($Q108:$R108)=0,"",ROUND(AVERAGE(Q108:R108),0)) | T108: =IF(COUNT(J108:P108,S108)=0,"",ROUND(AVERAGE(J108:P108,S108),0)) | U108: =IF(T108="","",_xlfn.RANK.AVG(T108,$T$8:$T$108))

Sheet TERM 3
A2: THIRD TERM | E2: GRADE LEVEL | F2: =IF('INPUT DATA'!F22="","",'INPUT DATA'!F22) | K2: ADVISER | M2: =IF('INPUT DATA'!F21="","",'INPUT DATA'!F21)
E3: SECTION | F3: =IF('INPUT DATA'!F23="","",'INPUT DATA'!F23)
A4: LEARNERS' NAMES | E4: LRN | G4: Date of Birth | H4: Age | I4: Sex | J4: Learning Areas | T4: Final Grade | U4: Rank
J5: Filipino | K5: English | L5: Mathematics | M5: Science | N5: AP | O5: GMRC/VE | P5: EPP/TLE | Q5: MAPEH
Q6: M A | R6: P E H | S6: Term Grade
A7: MALE
A8: 1 | B8: =IF('INPUT DATA'!L6="","",'INPUT DATA'!L6) | E8: =IF('INPUT DATA'!M6="","",'INPUT DATA'!M6) | G8: =IF('INPUT DATA'!N6="","",'INPUT DATA'!N6) | H8: =IF(G8="","",DATEDIF(G8,TODAY(),"Y")) | I8: =IF(B8="","","M") | S8: =IF(COUNT($Q8:$R8)=0,"",ROUND(AVERAGE(Q8:R8),0)) | T8: =IF(COUNT(J8:P8,S8)=0,"",ROUND(AVERAGE(J8:P8,S8),0)) | U8: =IF(T8="","",_xlfn.RANK.AVG(T8,$T$8:$T$108))
A9: 2 | B9: =IF('INPUT DATA'!L7="","",'INPUT DATA'!L7) | E9: =IF('INPUT DATA'!M7="","",'INPUT DATA'!M7) | G9: =IF('INPUT DATA'!N7="","",'INPUT DATA'!N7) | H9: =IF(G9="","",DATEDIF(G9,TODAY(),"Y")) | I9: =IF(B9="","","M") | S9: =IF(COUNT($Q9:$R9)=0,"",ROUND(AVERAGE(Q9:R9),0)) | T9: =IF(COUNT(J9:P9,S9)=0,"",ROUND(AVERAGE(J9:P9,S9),0)) | U9: =IF(T9="","",_xlfn.RANK.AVG(T9,$T$8:$T$108))
A10: 3 | B10: =IF('INPUT DATA'!L8="","",'INPUT DATA'!L8) | E10: =IF('INPUT DATA'!M8="","",'INPUT DATA'!M8) | G10: =IF('INPUT DATA'!N8="","",'INPUT DATA'!N8) | H10: =IF(G10="","",DATEDIF(G10,TODAY(),"Y")) | I10: =IF(B10="","","M") | S10: =IF(COUNT($Q10:$R10)=0,"",ROUND(AVERAGE(Q10:R10),0)) | T10: =IF(COUNT(J10:P10,S10)=0,"",ROUND(AVERAGE(J10:P10,S10),0)) | U10: =IF(T10="","",_xlfn.RANK.AVG(T10,$T$8:$T$108))
A11: 4 | B11: =IF('INPUT DATA'!L9="","",'INPUT DATA'!L9) | E11: =IF('INPUT DATA'!M9="","",'INPUT DATA'!M9) | G11: =IF('INPUT DATA'!N9="","",'INPUT DATA'!N9) | H11: =IF(G11="","",DATEDIF(G11,TODAY(),"Y")) | I11: =IF(B11="","","M") | S11: =IF(COUNT($Q11:$R11)=0,"",ROUND(AVERAGE(Q11:R11),0)) | T11: =IF(COUNT(J11:P11,S11)=0,"",ROUND(AVERAGE(J11:P11,S11),0)) | U11: =IF(T11="","",_xlfn.RANK.AVG(T11,$T$8:$T$108))
A12: 5 | B12: =IF('INPUT DATA'!L10="","",'INPUT DATA'!L10) | E12: =IF('INPUT DATA'!M10="","",'INPUT DATA'!M10) | G12: =IF('INPUT DATA'!N10="","",'INPUT DATA'!N10) | H12: =IF(G12="","",DATEDIF(G12,TODAY(),"Y")) | I12: =IF(B12="","","M") | S12: =IF(COUNT($Q12:$R12)=0,"",ROUND(AVERAGE(Q12:R12),0)) | T12: =IF(COUNT(J12:P12,S12)=0,"",ROUND(AVERAGE(J12:P12,S12),0)) | U12: =IF(T12="","",_xlfn.RANK.AVG(T12,$T$8:$T$108))
A13: 6 | B13: =IF('INPUT DATA'!L11="","",'INPUT DATA'!L11) | E13: =IF('INPUT DATA'!M11="","",'INPUT DATA'!M11) | G13: =IF('INPUT DATA'!N11="","",'INPUT DATA'!N11) | H13: =IF(G13="","",DATEDIF(G13,TODAY(),"Y")) | I13: =IF(B13="","","M") | S13: =IF(COUNT($Q13:$R13)=0,"",ROUND(AVERAGE(Q13:R13),0)) | T13: =IF(COUNT(J13:P13,S13)=0,"",ROUND(AVERAGE(J13:P13,S13),0)) | U13: =IF(T13="","",_xlfn.RANK.AVG(T13,$T$8:$T$108))
A14: 7 | B14: =IF('INPUT DATA'!L12="","",'INPUT DATA'!L12) | E14: =IF('INPUT DATA'!M12="","",'INPUT DATA'!M12) | G14: =IF('INPUT DATA'!N12="","",'INPUT DATA'!N12) | H14: =IF(G14="","",DATEDIF(G14,TODAY(),"Y")) | I14: =IF(B14="","","M") | S14: =IF(COUNT($Q14:$R14)=0,"",ROUND(AVERAGE(Q14:R14),0)) | T14: =IF(COUNT(J14:P14,S14)=0,"",ROUND(AVERAGE(J14:P14,S14),0)) | U14: =IF(T14="","",_xlfn.RANK.AVG(T14,$T$8:$T$108))
A15: 8 | B15: =IF('INPUT DATA'!L13="","",'INPUT DATA'!L13) | E15: =IF('INPUT DATA'!M13="","",'INPUT DATA'!M13) | G15: =IF('INPUT DATA'!N13="","",'INPUT DATA'!N13) | H15: =IF(G15="","",DATEDIF(G15,TODAY(),"Y")) | I15: =IF(B15="","","M") | S15: =IF(COUNT($Q15:$R15)=0,"",ROUND(AVERAGE(Q15:R15),0)) | T15: =IF(COUNT(J15:P15,S15)=0,"",ROUND(AVERAGE(J15:P15,S15),0)) | U15: =IF(T15="","",_xlfn.RANK.AVG(T15,$T$8:$T$108))
A16: 9 | B16: =IF('INPUT DATA'!L14="","",'INPUT DATA'!L14) | E16: =IF('INPUT DATA'!M14="","",'INPUT DATA'!M14) | G16: =IF('INPUT DATA'!N14="","",'INPUT DATA'!N14) | H16: =IF(G16="","",DATEDIF(G16,TODAY(),"Y")) | I16: =IF(B16="","","M") | S16: =IF(COUNT($Q16:$R16)=0,"",ROUND(AVERAGE(Q16:R16),0)) | T16: =IF(COUNT(J16:P16,S16)=0,"",ROUND(AVERAGE(J16:P16,S16),0)) | U16: =IF(T16="","",_xlfn.RANK.AVG(T16,$T$8:$T$108))
A17: 10 | B17: =IF('INPUT DATA'!L15="","",'INPUT DATA'!L15) | E17: =IF('INPUT DATA'!M15="","",'INPUT DATA'!M15) | G17: =IF('INPUT DATA'!N15="","",'INPUT DATA'!N15) | H17: =IF(G17="","",DATEDIF(G17,TODAY(),"Y")) | I17: =IF(B17="","","M") | S17: =IF(COUNT($Q17:$R17)=0,"",ROUND(AVERAGE(Q17:R17),0)) | T17: =IF(COUNT(J17:P17,S17)=0,"",ROUND(AVERAGE(J17:P17,S17),0)) | U17: =IF(T17="","",_xlfn.RANK.AVG(T17,$T$8:$T$108))
A18: 11 | B18: =IF('INPUT DATA'!L16="","",'INPUT DATA'!L16) | E18: =IF('INPUT DATA'!M16="","",'INPUT DATA'!M16) | G18: =IF('INPUT DATA'!N16="","",'INPUT DATA'!N16) | H18: =IF(G18="","",DATEDIF(G18,TODAY(),"Y")) | I18: =IF(B18="","","M") | S18: =IF(COUNT($Q18:$R18)=0,"",ROUND(AVERAGE(Q18:R18),0)) | T18: =IF(COUNT(J18:P18,S18)=0,"",ROUND(AVERAGE(J18:P18,S18),0)) | U18: =IF(T18="","",_xlfn.RANK.AVG(T18,$T$8:$T$108))
A19: 12 | B19: =IF('INPUT DATA'!L17="","",'INPUT DATA'!L17) | E19: =IF('INPUT DATA'!M17="","",'INPUT DATA'!M17) | G19: =IF('INPUT DATA'!N17="","",'INPUT DATA'!N17) | H19: =IF(G19="","",DATEDIF(G19,TODAY(),"Y")) | I19: =IF(B19="","","M") | S19: =IF(COUNT($Q19:$R19)=0,"",ROUND(AVERAGE(Q19:R19),0)) | T19: =IF(COUNT(J19:P19,S19)=0,"",ROUND(AVERAGE(J19:P19,S19),0)) | U19: =IF(T19="","",_xlfn.RANK.AVG(T19,$T$8:$T$108))
... A57: 50 | B57: =IF('INPUT DATA'!L55="","",'INPUT DATA'!L55) | E57: =IF('INPUT DATA'!M55="","",'INPUT DATA'!M55) | G57: =IF('INPUT DATA'!N55="","",'INPUT DATA'!N55) | H57: =IF(G57="","",DATEDIF(G57,TODAY(),"Y")) | I57: =IF(B57="","","M") | S57: =IF(COUNT($Q57:$R57)=0,"",ROUND(AVERAGE(Q57:R57),0)) | T57: =IF(COUNT(J57:P57,S57)=0,"",ROUND(AVERAGE(J57:P57,S57),0)) | U57: =IF(T57="","",_xlfn.RANK.AVG(T57,$T$8:$T$108))
A58: FEMALE
A59: 1 | B59: =IF('INPUT DATA'!Q6="","",'INPUT DATA'!Q6) | E59: =IF('INPUT DATA'!R6="","",'INPUT DATA'!R6) | G59: =IF('INPUT DATA'!S6="","",'INPUT DATA'!S6) | H59: =IF(G59="","",DATEDIF(G59,TODAY(),"Y")) | I59: =IF(B59="","","F") | S59: =IF(COUNT($Q59:$R59)=0,"",ROUND(AVERAGE(Q59:R59),0)) | T59: =IF(COUNT(J59:P59,S59)=0,"",ROUND(AVERAGE(J59:P59,S59),0)) | U59: =IF(T59="","",_xlfn.RANK.AVG(T59,$T$8:$T$108))
A60: 2 | B60: =IF('INPUT DATA'!Q7="","",'INPUT DATA'!Q7) | E60: =IF('INPUT DATA'!R7="","",'INPUT DATA'!R7) | G60: =IF('INPUT DATA'!S7="","",'INPUT DATA'!S7) | H60: =IF(G60="","",DATEDIF(G60,TODAY(),"Y")) | I60: =IF(B60="","","F") | S60: =IF(COUNT($Q60:$R60)=0,"",ROUND(AVERAGE(Q60:R60),0)) | T60: =IF(COUNT(J60:P60,S60)=0,"",ROUND(AVERAGE(J60:P60,S60),0)) | U60: =IF(T60="","",_xlfn.RANK.AVG(T60,$T$8:$T$108))
A61: 3 | B61: =IF('INPUT DATA'!Q8="","",'INPUT DATA'!Q8) | E61: =IF('INPUT DATA'!R8="","",'INPUT DATA'!R8) | G61: =IF('INPUT DATA'!S8="","",'INPUT DATA'!S8) | H61: =IF(G61="","",DATEDIF(G61,TODAY(),"Y")) | I61: =IF(B61="","","F") | S61: =IF(COUNT($Q61:$R61)=0,"",ROUND(AVERAGE(Q61:R61),0)) | T61: =IF(COUNT(J61:P61,S61)=0,"",ROUND(AVERAGE(J61:P61,S61),0)) | U61: =IF(T61="","",_xlfn.RANK.AVG(T61,$T$8:$T$108))
A62: 4 | B62: =IF('INPUT DATA'!Q9="","",'INPUT DATA'!Q9) | E62: =IF('INPUT DATA'!R9="","",'INPUT DATA'!R9) | G62: =IF('INPUT DATA'!S9="","",'INPUT DATA'!S9) | H62: =IF(G62="","",DATEDIF(G62,TODAY(),"Y")) | I62: =IF(B62="","","F") | S62: =IF(COUNT($Q62:$R62)=0,"",ROUND(AVERAGE(Q62:R62),0)) | T62: =IF(COUNT(J62:P62,S62)=0,"",ROUND(AVERAGE(J62:P62,S62),0)) | U62: =IF(T62="","",_xlfn.RANK.AVG(T62,$T$8:$T$108))
A63: 5 | B63: =IF('INPUT DATA'!Q10="","",'INPUT DATA'!Q10) | E63: =IF('INPUT DATA'!R10="","",'INPUT DATA'!R10) | G63: =IF('INPUT DATA'!S10="","",'INPUT DATA'!S10) | H63: =IF(G63="","",DATEDIF(G63,TODAY(),"Y")) | I63: =IF(B63="","","F") | S63: =IF(COUNT($Q63:$R63)=0,"",ROUND(AVERAGE(Q63:R63),0)) | T63: =IF(COUNT(J63:P63,S63)=0,"",ROUND(AVERAGE(J63:P63,S63),0)) | U63: =IF(T63="","",_xlfn.RANK.AVG(T63,$T$8:$T$108))
A64: 6 | B64: =IF('INPUT DATA'!Q11="","",'INPUT DATA'!Q11) | E64: =IF('INPUT DATA'!R11="","",'INPUT DATA'!R11) | G64: =IF('INPUT DATA'!S11="","",'INPUT DATA'!S11) | H64: =IF(G64="","",DATEDIF(G64,TODAY(),"Y")) | I64: =IF(B64="","","F") | S64: =IF(COUNT($Q64:$R64)=0,"",ROUND(AVERAGE(Q64:R64),0)) | T64: =IF(COUNT(J64:P64,S64)=0,"",ROUND(AVERAGE(J64:P64,S64),0)) | U64: =IF(T64="","",_xlfn.RANK.AVG(T64,$T$8:$T$108))
A65: 7 | B65: =IF('INPUT DATA'!Q12="","",'INPUT DATA'!Q12) | E65: =IF('INPUT DATA'!R12="","",'INPUT DATA'!R12) | G65: =IF('INPUT DATA'!S12="","",'INPUT DATA'!S12) | H65: =IF(G65="","",DATEDIF(G65,TODAY(),"Y")) | I65: =IF(B65="","","F") | S65: =IF(COUNT($Q65:$R65)=0,"",ROUND(AVERAGE(Q65:R65),0)) | T65: =IF(COUNT(J65:P65,S65)=0,"",ROUND(AVERAGE(J65:P65,S65),0)) | U65: =IF(T65="","",_xlfn.RANK.AVG(T65,$T$8:$T$108))
A66: 8 | B66: =IF('INPUT DATA'!Q13="","",'INPUT DATA'!Q13) | E66: =IF('INPUT DATA'!R13="","",'INPUT DATA'!R13) | G66: =IF('INPUT DATA'!S13="","",'INPUT DATA'!S13) | H66: =IF(G66="","",DATEDIF(G66,TODAY(),"Y")) | I66: =IF(B66="","","F") | S66: =IF(COUNT($Q66:$R66)=0,"",ROUND(AVERAGE(Q66:R66),0)) | T66: =IF(COUNT(J66:P66,S66)=0,"",ROUND(AVERAGE(J66:P66,S66),0)) | U66: =IF(T66="","",_xlfn.RANK.AVG(T66,$T$8:$T$108))
A67: 9 | B67: =IF('INPUT DATA'!Q14="","",'INPUT DATA'!Q14) | E67: =IF('INPUT DATA'!R14="","",'INPUT DATA'!R14) | G67: =IF('INPUT DATA'!S14="","",'INPUT DATA'!S14) | H67: =IF(G67="","",DATEDIF(G67,TODAY(),"Y")) | I67: =IF(B67="","","F") | S67: =IF(COUNT($Q67:$R67)=0,"",ROUND(AVERAGE(Q67:R67),0)) | T67: =IF(COUNT(J67:P67,S67)=0,"",ROUND(AVERAGE(J67:P67,S67),0)) | U67: =IF(T67="","",_xlfn.RANK.AVG(T67,$T$8:$T$108))
A68: 10 | B68: =IF('INPUT DATA'!Q15="","",'INPUT DATA'!Q15) | E68: =IF('INPUT DATA'!R15="","",'INPUT DATA'!R15) | G68: =IF('INPUT DATA'!S15="","",'INPUT DATA'!S15) | H68: =IF(G68="","",DATEDIF(G68,TODAY(),"Y")) | I68: =IF(B68="","","F") | S68: =IF(COUNT($Q68:$R68)=0,"",ROUND(AVERAGE(Q68:R68),0)) | T68: =IF(COUNT(J68:P68,S68)=0,"",ROUND(AVERAGE(J68:P68,S68),0)) | U68: =IF(T68="","",_xlfn.RANK.AVG(T68,$T$8:$T$108))
A69: 11 | B69: =IF('INPUT DATA'!Q16="","",'INPUT DATA'!Q16) | E69: =IF('INPUT DATA'!R16="","",'INPUT DATA'!R16) | G69: =IF('INPUT DATA'!S16="","",'INPUT DATA'!S16) | H69: =IF(G69="","",DATEDIF(G69,TODAY(),"Y")) | I69: =IF(B69="","","F") | S69: =IF(COUNT($Q69:$R69)=0,"",ROUND(AVERAGE(Q69:R69),0)) | T69: =IF(COUNT(J69:P69,S69)=0,"",ROUND(AVERAGE(J69:P69,S69),0)) | U69: =IF(T69="","",_xlfn.RANK.AVG(T69,$T$8:$T$108))
A70: 12 | B70: =IF('INPUT DATA'!Q17="","",'INPUT DATA'!Q17) | E70: =IF('INPUT DATA'!R17="","",'INPUT DATA'!R17) | G70: =IF('INPUT DATA'!S17="","",'INPUT DATA'!S17) | H70: =IF(G70="","",DATEDIF(G70,TODAY(),"Y")) | I70: =IF(B70="","","F") | S70: =IF(COUNT($Q70:$R70)=0,"",ROUND(AVERAGE(Q70:R70),0)) | T70: =IF(COUNT(J70:P70,S70)=0,"",ROUND(AVERAGE(J70:P70,S70),0)) | U70: =IF(T70="","",_xlfn.RANK.AVG(T70,$T$8:$T$108))
... A108: 50 | B108: =IF('INPUT DATA'!Q55="","",'INPUT DATA'!Q55) | E108: =IF('INPUT DATA'!R55="","",'INPUT DATA'!R55) | G108: =IF('INPUT DATA'!S55="","",'INPUT DATA'!S55) | H108: =IF(G108="","",DATEDIF(G108,TODAY(),"Y")) | I108: =IF(B108="","","F") | S108: =IF(COUNT($Q108:$R108)=0,"",ROUND(AVERAGE(Q108:R108),0)) | T108: =IF(COUNT(J108:P108,S108)=0,"",ROUND(AVERAGE(J108:P108,S108),0)) | U108: =IF(T108="","",_xlfn.RANK.AVG(T108,$T$8:$T$108))

Sheet ATTENDANCE RECORD SUMMARY
A2: LEARNERS' NAMES | E2: GRADE LEVEL | G2: =IF('INPUT DATA'!F22="","",'INPUT DATA'!F22) | J2: ADVISER | K2: =IF('INPUT DATA'!F21="","",'INPUT DATA'!F21)
E3: SECTION | G3: =IF('INPUT DATA'!F23="","",'INPUT DATA'!F23)
E4: JUN | F4: JUL | G4: AUG | H4: SEP | I4: OCT | J4: NOV | K4: DEC | L4: JAN | M4: FEB | N4: MAR | O4: APRIL
A5: MALE
A6: 1 | B6: =IF('INPUT DATA'!L6="","",'INPUT DATA'!L6)
A7: 2 | B7: =IF('INPUT DATA'!L7="","",'INPUT DATA'!L7)
A8: 3 | B8: =IF('INPUT DATA'!L8="","",'INPUT DATA'!L8)
A9: 4 | B9: =IF('INPUT DATA'!L9="","",'INPUT DATA'!L9)
A10: 5 | B10: =IF('INPUT DATA'!L10="","",'INPUT DATA'!L10)
A11: 6 | B11: =IF('INPUT DATA'!L11="","",'INPUT DATA'!L11)
A12: 7 | B12: =IF('INPUT DATA'!L12="","",'INPUT DATA'!L12)
A13: 8 | B13: =IF('INPUT DATA'!L13="","",'INPUT DATA'!L13)
A14: 9 | B14: =IF('INPUT DATA'!L14="","",'INPUT DATA'!L14)
A15: 10 | B15: =IF('INPUT DATA'!L15="","",'INPUT DATA'!L15)
A16: 11 | B16: =IF('INPUT DATA'!L16="","",'INPUT DATA'!L16)
A17: 12 | B17: =IF('INPUT DATA'!L17="","",'INPUT DATA'!L17)
... A55: 50 | B55: =IF('INPUT DATA'!L55="","",'INPUT DATA'!L55)
A56: FEMALE
A57: 1 | B57: =IF('INPUT DATA'!Q6="","",'INPUT DATA'!Q6)
A58: 2 | B58: =IF('INPUT DATA'!Q7="","",'INPUT DATA'!Q7)
A59: 3 | B59: =IF('INPUT DATA'!Q8="","",'INPUT DATA'!Q8)
A60: 4 | B60: =IF('INPUT DATA'!Q9="","",'INPUT DATA'!Q9)
A61: 5 | B61: =IF('INPUT DATA'!Q10="","",'INPUT DATA'!Q10)
A62: 6 | B62: =IF('INPUT DATA'!Q11="","",'INPUT DATA'!Q11)
A63: 7 | B63: =IF('INPUT DATA'!Q12="","",'INPUT DATA'!Q12)
A64: 8 | B64: =IF('INPUT DATA'!Q13="","",'INPUT DATA'!Q13)
A65: 9 | B65: =IF('INPUT DATA'!Q14="","",'INPUT DATA'!Q14)
A66: 10 | B66: =IF('INPUT DATA'!Q15="","",'INPUT DATA'!Q15)
A67: 11 | B67: =IF('INPUT DATA'!Q16="","",'INPUT DATA'!Q16)
A68: 12 | B68: =IF('INPUT DATA'!Q17="","",'INPUT DATA'!Q17)
... A106: 50 | B106: =IF('INPUT DATA'!Q55="","",'INPUT DATA'!Q55)
A108: TOTAL NUMBER OF SCHOOL DAYS | D108: TOTAL | E108: JUN | F108: JUL | G108: AUG | H108: SEP | I108: OCT | J108: NOV | K108: DEC | L108: JAN | M108: FEB | N108: MAR | O108: APR
D109: =SUM(E109:O109) -> 201 | E109: 20 | F109: 20 | G109: 20 | H109: 20 | I109: 20 | J109: 20 | K109: 20 | L109: 18 | M109: 18 | N109: 20 | O109: 5

Sheet GAKUSEKI
A1: region | B1: division | C1: district | D1: location | E1: school_name | F1: school_year | G1: adviser | H1: grade | I1: section | J1: school_head | K1: name | L1: lrn | M1: age | N1: sex | O1: t1.filipino | P1: t2.filipino | Q1: t3.filipino | R1: final_grade.filipino | S1: remarks.filipino | T1: t1.english | U1: t2.english | V1: t3.english | W1: final_grade.english | X1: remarks.english | Y1: t1.mathematics | Z1: t2.mathematics | AA1: t3.mathematics | AB1: final_grade.mathematics | AC1: remarks.mathematics | AD1: t1.science | AE1: t2.science | AF1: t3.science | AG1: final_grade.science | AH1: remarks.science | AI1: t1.araling_panlipunan | AJ1: t2.araling_panlipunan | AK1: t3.araling_panlipunan | AL1: final_grade.araling_panlipunan | AM1: remarks.araling_panlipunan | AN1: t1.gmrc | AO1: t2.gmrc | AP1: t3.gmrc | AQ1: final_grade.gmrc | AR1: remarks.gmrc | AS1: t1.epp | AT1: t2.epp | AU1: t3.epp | AV1: final_grade.epp | AW1: remarks.epp | AX1: t1.mapeh | AY1: t2.mapeh | AZ1: t3.mapeh | BA1: final_grade.mapeh | BB1: remarks.mapeh | BC1: t1.music_and_arts | BD1: t2.music_and_arts | BE1: t3.music_and_arts | BF1: final_grade.music_and_arts | BG1: remarks.music_and_arts | BH1: t1.pe_and_health | BI1: t2.pe_and_health | BJ1: t3.pe_and_health | BK1: final_grade.pe_and_health | BL1: remarks.pe_and_health | BM1: general_average | BN1: general_remarks
A2: =IF($K2="","",IF('INPUT DATA'!F5="","",'INPUT DATA'!F5)) | B2: =IF($K2="","",IF('INPUT DATA'!F6="","",'INPUT DATA'!F6)) | C2: =IF($K2="","",IF('INPUT DATA'!F8="","",'INPUT DATA'!F8)) | D2: =IF($K2="","",IF('INPUT DATA'!F7="","",'INPUT DATA'!F7)) | E2: =IF($K2="","",IF('INPUT DATA'!F11="","",'INPUT DATA'!F11)) | F2: =IF($K2="","",IF('INPUT DATA'!F13="","",'INPUT DATA'!F13)) | G2: =IF($K2="","",IF('INPUT DATA'!F21="","",'INPUT DATA'!F21)) | H2: =IF($K2="","",IF('INPUT DATA'!F22="","",'INPUT DATA'!F22)) | I2: =IF($K2="","",IF('INPUT DATA'!F23="","",'INPUT DATA'!F23)) | J2: =IF($K2="","",IF('INPUT DATA'!F14="","",'INPUT DATA'!F14)) | K2: =IF('INPUT DATA'!L6="","",'INPUT DATA'!L6) | L2: =IF('INPUT DATA'!M6="","",'INPUT DATA'!M6) | M2: =IF('TERM 1'!H8="","",'TERM 1'!H8) | N2: =IF(K2="","","M") | O2: =IF('TERM 1'!J8="","",'TERM 1'!J8) | P2: =IF('TERM 2'!J8="","",'TERM 2'!J8) | Q2: =IF('TERM 3'!J8="","",'TERM 3'!J8) | R2: =IF(COUNT(O2:Q2)<3,"",ROUND(AVERAGE(O2:Q2),0)) | S2: =IF(R2="","",IF(R2>=75,"Passed","Failed")) | T2: =IF('TERM 1'!K8="","",'TERM 1'!K8) | U2: =IF('TERM 2'!K8="","",'TERM 2'!K8) | V2: =IF('TERM 3'!K8="","",'TERM 3'!K8) | W2: =IF(COUNT(T2:V2)<3,"",ROUND(AVERAGE(T2:V2),0)) | X2: =IF(W2="","",IF(W2>=75,"Passed","Failed")) | Y2: =IF('TERM 1'!L8="","",'TERM 1'!L8) | Z2: =IF('TERM 2'!L8="","",'TERM 2'!L8) | AA2: =IF('TERM 3'!L8="","",'TERM 3'!L8) | AB2: =IF(COUNT(Y2:AA2)<3,"",ROUND(AVERAGE(Y2:AA2),0)) | AC2: =IF(AB2="","",IF(AB2>=75,"Passed","Failed")) | AD2: =IF('TERM 1'!M8="","",'TERM 1'!M8) | AE2: =IF('TERM 2'!M8="","",'TERM 2'!M8) | AF2: =IF('TERM 3'!M8="","",'TERM 3'!M8) | AG2: =IF(COUNT(AD2:AF2)<3,"",ROUND(AVERAGE(AD2:AF2),0)) | AH2: =IF(AG2="","",IF(AG2>=75,"Passed","Failed")) | AI2: =IF('TERM 1'!N8="","",'TERM 1'!N8) | AJ2: =IF('TERM 2'!N8="","",'TERM 2'!N8) | AK2: =IF('TERM 3'!N8="","",'TERM 3'!N8) | AL2: =IF(COUNT(AI2:AK2)<3,"",ROUND(AVERAGE(AI2:AK2),0)) | AM2: =IF(AL2="","",IF(AL2>=75,"Passed","Failed")) | AN2: =IF('TERM 1'!O8="","",'TERM 1'!O8) | AO2: =IF('TERM 2'!O8="","",'TERM 2'!O8) | AP2: =IF('TERM 3'!O8="","",'TERM 3'!O8) | AQ2: =IF(COUNT(AN2:AP2)<3,"",ROUND(AVERAGE(AN2:AP2),0)) | AR2: =IF(AQ2="","",IF(AQ2>=75,"Passed","Failed")) | AS2: =IF('TERM 1'!P8="","",'TERM 1'!P8) | AT2: =IF('TERM 2'!P8="","",'TERM 2'!P8) | AU2: =IF('TERM 3'!P8="","",'TERM 3'!P8) | AV2: =IF(COUNT(AS2:AU2)<3,"",ROUND(AVERAGE(AS2:AU2),0)) | AW2: =IF(AV2="","",IF(AV2>=75,"Passed","Failed")) | AX2: =IF('TERM 1'!S8="","",'TERM 1'!S8) | AY2: =IF('TERM 2'!S8="","",'TERM 2'!S8) | AZ2: =IF('TERM 3'!S8="","",'TERM 3'!S8) | BA2: =IF(COUNT(AX2:AZ2)<3,"",ROUND(AVERAGE(AX2:AZ2),0)) | BB2: =IF(BA2="","",IF(BA2>=75,"Passed","Failed")) | BC2: =IF('TERM 1'!Q8="","",'TERM 1'!Q8) | BD2: =IF('TERM 2'!Q8="","",'TERM 2'!Q8) | BE2: =IF('TERM 3'!Q8="","",'TERM 3'!Q8) | BF2: =IF(COUNT(BC2:BE2)<3,"",ROUND(AVERAGE(BC2:BE2),0)) | BG2: =IF(BF2="","",IF(BF2>=75,"Passed","Failed")) | BH2: =IF('TERM 1'!R8="","",'TERM 1'!R8) | BI2: =IF('TERM 2'!R8="","",'TERM 2'!R8) | BJ2: =IF('TERM 3'!R8="","",'TERM 3'!R8) | BK2: =IF(COUNT(BH2:BJ2)<3,"",ROUND(AVERAGE(BH2:BJ2),0)) | BL2: =IF(BK2="","",IF(BK2>=75,"Passed","Failed")) | BM2: =IF(COUNT(R2,W2,AB2,AG2,AL2,AQ2,AV2,BA2)<8,"",ROUND(AVERAGE(R2,W2,AB2,AG2,AL2,AQ2,AV2,BA2),0)) | BN2: =IF(BM2="","",IF(BM2>=75,"Passed","Failed"))
A3: =IF($K3="","",IF('INPUT DATA'!F5="","",'INPUT DATA'!F5)) | B3: =IF($K3="","",IF('INPUT DATA'!F6="","",'INPUT DATA'!F6)) | C3: =IF($K3="","",IF('INPUT DATA'!F8="","",'INPUT DATA'!F8)) | D3: =IF($K3="","",IF('INPUT DATA'!F7="","",'INPUT DATA'!F7)) | E3: =IF($K3="","",IF('INPUT DATA'!F11="","",'INPUT DATA'!F11)) | F3: =IF($K3="","",IF('INPUT DATA'!F13="","",'INPUT DATA'!F13)) | G3: =IF($K3="","",IF('INPUT DATA'!F21="","",'INPUT DATA'!F21)) | H3: =IF($K3="","",IF('INPUT DATA'!F22="","",'INPUT DATA'!F22)) | I3: =IF($K3="","",IF('INPUT DATA'!F23="","",'INPUT DATA'!F23)) | J3: =IF($K3="","",IF('INPUT DATA'!F14="","",'INPUT DATA'!F14)) | K3: =IF('INPUT DATA'!L7="","",'INPUT DATA'!L7) | L3: =IF('INPUT DATA'!M7="","",'INPUT DATA'!M7) | M3: =IF('TERM 1'!H9="","",'TERM 1'!H9) | N3: =IF(K3="","","M") | O3: =IF('TERM 1'!J9="","",'TERM 1'!J9) | P3: =IF('TERM 2'!J9="","",'TERM 2'!J9) | Q3: =IF('TERM 3'!J9="","",'TERM 3'!J9) | R3: =IF(COUNT(O3:Q3)<3,"",ROUND(AVERAGE(O3:Q3),0)) | S3: =IF(R3="","",IF(R3>=75,"Passed","Failed")) | T3: =IF('TERM 1'!K9="","",'TERM 1'!K9) | U3: =IF('TERM 2'!K9="","",'TERM 2'!K9) | V3: =IF('TERM 3'!K9="","",'TERM 3'!K9) | W3: =IF(COUNT(T3:V3)<3,"",ROUND(AVERAGE(T3:V3),0)) | X3: =IF(W3="","",IF(W3>=75,"Passed","Failed")) | Y3: =IF('TERM 1'!L9="","",'TERM 1'!L9) | Z3: =IF('TERM 2'!L9="","",'TERM 2'!L9) | AA3: =IF('TERM 3'!L9="","",'TERM 3'!L9) | AB3: =IF(COUNT(Y3:AA3)<3,"",ROUND(AVERAGE(Y3:AA3),0)) | AC3: =IF(AB3="","",IF(AB3>=75,"Passed","Failed")) | AD3: =IF('TERM 1'!M9="","",'TERM 1'!M9) | AE3: =IF('TERM 2'!M9="","",'TERM 2'!M9) | AF3: =IF('TERM 3'!M9="","",'TERM 3'!M9) | AG3: =IF(COUNT(AD3:AF3)<3,"",ROUND(AVERAGE(AD3:AF3),0)) | AH3: =IF(AG3="","",IF(AG3>=75,"Passed","Failed")) | AI3: =IF('TERM 1'!N9="","",'TERM 1'!N9) | AJ3: =IF('TERM 2'!N9="","",'TERM 2'!N9) | AK3: =IF('TERM 3'!N9="","",'TERM 3'!N9) | AL3: =IF(COUNT(AI3:AK3)<3,"",ROUND(AVERAGE(AI3:AK3),0)) | AM3: =IF(AL3="","",IF(AL3>=75,"Passed","Failed")) | AN3: =IF('TERM 1'!O9="","",'TERM 1'!O9) | AO3: =IF('TERM 2'!O9="","",'TERM 2'!O9) | AP3: =IF('TERM 3'!O9="","",'TERM 3'!O9) | AQ3: =IF(COUNT(AN3:AP3)<3,"",ROUND(AVERAGE(AN3:AP3),0)) | AR3: =IF(AQ3="","",IF(AQ3>=75,"Passed","Failed")) | AS3: =IF('TERM 1'!P9="","",'TERM 1'!P9) | AT3: =IF('TERM 2'!P9="","",'TERM 2'!P9) | AU3: =IF('TERM 3'!P9="","",'TERM 3'!P9) | AV3: =IF(COUNT(AS3:AU3)<3,"",ROUND(AVERAGE(AS3:AU3),0)) | AW3: =IF(AV3="","",IF(AV3>=75,"Passed","Failed")) | AX3: =IF('TERM 1'!S9="","",'TERM 1'!S9) | AY3: =IF('TERM 2'!S9="","",'TERM 2'!S9) | AZ3: =IF('TERM 3'!S9="","",'TERM 3'!S9) | BA3: =IF(COUNT(AX3:AZ3)<3,"",ROUND(AVERAGE(AX3:AZ3),0)) | BB3: =IF(BA3="","",IF(BA3>=75,"Passed","Failed")) | BC3: =IF('TERM 1'!Q9="","",'TERM 1'!Q9) | BD3: =IF('TERM 2'!Q9="","",'TERM 2'!Q9) | BE3: =IF('TERM 3'!Q9="","",'TERM 3'!Q9) | BF3: =IF(COUNT(BC3:BE3)<3,"",ROUND(AVERAGE(BC3:BE3),0)) | BG3: =IF(BF3="","",IF(BF3>=75,"Passed","Failed")) | BH3: =IF('TERM 1'!R9="","",'TERM 1'!R9) | BI3: =IF('TERM 2'!R9="","",'TERM 2'!R9) | BJ3: =IF('TERM 3'!R9="","",'TERM 3'!R9) | BK3: =IF(COUNT(BH3:BJ3)<3,"",ROUND(AVERAGE(BH3:BJ3),0)) | BL3: =IF(BK3="","",IF(BK3>=75,"Passed","Failed")) | BM3: =IF(COUNT(R3,W3,AB3,AG3,AL3,AQ3,AV3,BA3)<8,"",ROUND(AVERAGE(R3,W3,AB3,AG3,AL3,AQ3,AV3,BA3),0)) | BN3: =IF(BM3="","",IF(BM3>=75,"Passed","Failed"))
A4: =IF($K4="","",IF('INPUT DATA'!F5="","",'INPUT DATA'!F5)) | B4: =IF($K4="","",IF('INPUT DATA'!F6="","",'INPUT DATA'!F6)) | C4: =IF($K4="","",IF('INPUT DATA'!F8="","",'INPUT DATA'!F8)) | D4: =IF($K4="","",IF('INPUT DATA'!F7="","",'INPUT DATA'!F7)) | E4: =IF($K4="","",IF('INPUT DATA'!F11="","",'INPUT DATA'!F11)) | F4: =IF($K4="","",IF('INPUT DATA'!F13="","",'INPUT DATA'!F13)) | G4: =IF($K4="","",IF('INPUT DATA'!F21="","",'INPUT DATA'!F21)) | H4: =IF($K4="","",IF('INPUT DATA'!F22="","",'INPUT DATA'!F22)) | I4: =IF($K4="","",IF('INPUT DATA'!F23="","",'INPUT DATA'!F23)) | J4: =IF($K4="","",IF('INPUT DATA'!F14="","",'INPUT DATA'!F14)) | K4: =IF('INPUT DATA'!L8="","",'INPUT DATA'!L8) | L4: =IF('INPUT DATA'!M8="","",'INPUT DATA'!M8) | M4: =IF('TERM 1'!H10="","",'TERM 1'!H10) | N4: =IF(K4="","","M") | O4: =IF('TERM 1'!J10="","",'TERM 1'!J10) | P4: =IF('TERM 2'!J10="","",'TERM 2'!J10) | Q4: =IF('TERM 3'!J10="","",'TERM 3'!J10) | R4: =IF(COUNT(O4:Q4)<3,"",ROUND(AVERAGE(O4:Q4),0)) | S4: =IF(R4="","",IF(R4>=75,"Passed","Failed")) | T4: =IF('TERM 1'!K10="","",'TERM 1'!K10) | U4: =IF('TERM 2'!K10="","",'TERM 2'!K10) | V4: =IF('TERM 3'!K10="","",'TERM 3'!K10) | W4: =IF(COUNT(T4:V4)<3,"",ROUND(AVERAGE(T4:V4),0)) | X4: =IF(W4="","",IF(W4>=75,"Passed","Failed")) | Y4: =IF('TERM 1'!L10="","",'TERM 1'!L10) | Z4: =IF('TERM 2'!L10="","",'TERM 2'!L10) | AA4: =IF('TERM 3'!L10="","",'TERM 3'!L10) | AB4: =IF(COUNT(Y4:AA4)<3,"",ROUND(AVERAGE(Y4:AA4),0)) | AC4: =IF(AB4="","",IF(AB4>=75,"Passed","Failed")) | AD4: =IF('TERM 1'!M10="","",'TERM 1'!M10) | AE4: =IF('TERM 2'!M10="","",'TERM 2'!M10) | AF4: =IF('TERM 3'!M10="","",'TERM 3'!M10) | AG4: =IF(COUNT(AD4:AF4)<3,"",ROUND(AVERAGE(AD4:AF4),0)) | AH4: =IF(AG4="","",IF(AG4>=75,"Passed","Failed")) | AI4: =IF('TERM 1'!N10="","",'TERM 1'!N10) | AJ4: =IF('TERM 2'!N10="","",'TERM 2'!N10) | AK4: =IF('TERM 3'!N10="","",'TERM 3'!N10) | AL4: =IF(COUNT(AI4:AK4)<3,"",ROUND(AVERAGE(AI4:AK4),0)) | AM4: =IF(AL4="","",IF(AL4>=75,"Passed","Failed")) | AN4: =IF('TERM 1'!O10="","",'TERM 1'!O10) | AO4: =IF('TERM 2'!O10="","",'TERM 2'!O10) | AP4: =IF('TERM 3'!O10="","",'TERM 3'!O10) | AQ4: =IF(COUNT(AN4:AP4)<3,"",ROUND(AVERAGE(AN4:AP4),0)) | AR4: =IF(AQ4="","",IF(AQ4>=75,"Passed","Failed")) | AS4: =IF('TERM 1'!P10="","",'TERM 1'!P10) | AT4: =IF('TERM 2'!P10="","",'TERM 2'!P10) | AU4: =IF('TERM 3'!P10="","",'TERM 3'!P10) | AV4: =IF(COUNT(AS4:AU4)<3,"",ROUND(AVERAGE(AS4:AU4),0)) | AW4: =IF(AV4="","",IF(AV4>=75,"Passed","Failed")) | AX4: =IF('TERM 1'!S10="","",'TERM 1'!S10) | AY4: =IF('TERM 2'!S10="","",'TERM 2'!S10) | AZ4: =IF('TERM 3'!S10="","",'TERM 3'!S10) | BA4: =IF(COUNT(AX4:AZ4)<3,"",ROUND(AVERAGE(AX4:AZ4),0)) | BB4: =IF(BA4="","",IF(BA4>=75,"Passed","Failed")) | BC4: =IF('TERM 1'!Q10="","",'TERM 1'!Q10) | BD4: =IF('TERM 2'!Q10="","",'TERM 2'!Q10) | BE4: =IF('TERM 3'!Q10="","",'TERM 3'!Q10) | BF4: =IF(COUNT(BC4:BE4)<3,"",ROUND(AVERAGE(BC4:BE4),0)) | BG4: =IF(BF4="","",IF(BF4>=75,"Passed","Failed")) | BH4: =IF('TERM 1'!R10="","",'TERM 1'!R10) | BI4: =IF('TERM 2'!R10="","",'TERM 2'!R10) | BJ4: =IF('TERM 3'!R10="","",'TERM 3'!R10) | BK4: =IF(COUNT(BH4:BJ4)<3,"",ROUND(AVERAGE(BH4:BJ4),0)) | BL4: =IF(BK4="","",IF(BK4>=75,"Passed","Failed")) | BM4: =IF(COUNT(R4,W4,AB4,AG4,AL4,AQ4,AV4,BA4)<8,"",ROUND(AVERAGE(R4,W4,AB4,AG4,AL4,AQ4,AV4,BA4),0)) | BN4: =IF(BM4="","",IF(BM4>=75,"Passed","Failed"))
A5: =IF($K5="","",IF('INPUT DATA'!F5="","",'INPUT DATA'!F5)) | B5: =IF($K5="","",IF('INPUT DATA'!F6="","",'INPUT DATA'!F6)) | C5: =IF($K5="","",IF('INPUT DATA'!F8="","",'INPUT DATA'!F8)) | D5: =IF($K5="","",IF('INPUT DATA'!F7="","",'INPUT DATA'!F7)) | E5: =IF($K5="","",IF('INPUT DATA'!F11="","",'INPUT DATA'!F11)) | F5: =IF($K5="","",IF('INPUT DATA'!F13="","",'INPUT DATA'!F13)) | G5: =IF($K5="","",IF('INPUT DATA'!F21="","",'INPUT DATA'!F21)) | H5: =IF($K5="","",IF('INPUT DATA'!F22="","",'INPUT DATA'!F22)) | I5: =IF($K5="","",IF('INPUT DATA'!F23="","",'INPUT DATA'!F23)) | J5: =IF($K5="","",IF('INPUT DATA'!F14="","",'INPUT DATA'!F14)) | K5: =IF('INPUT DATA'!L9="","",'INPUT DATA'!L9) | L5: =IF('INPUT DATA'!M9="","",'INPUT DATA'!M9) | M5: =IF('TERM 1'!H11="","",'TERM 1'!H11) | N5: =IF(K5="","","M") | O5: =IF('TERM 1'!J11="","",'TERM 1'!J11) | P5: =IF('TERM 2'!J11="","",'TERM 2'!J11) | Q5: =IF('TERM 3'!J11="","",'TERM 3'!J11) | R5: =IF(COUNT(O5:Q5)<3,"",ROUND(AVERAGE(O5:Q5),0)) | S5: =IF(R5="","",IF(R5>=75,"Passed","Failed")) | T5: =IF('TERM 1'!K11="","",'TERM 1'!K11) | U5: =IF('TERM 2'!K11="","",'TERM 2'!K11) | V5: =IF('TERM 3'!K11="","",'TERM 3'!K11) | W5: =IF(COUNT(T5:V5)<3,"",ROUND(AVERAGE(T5:V5),0)) | X5: =IF(W5="","",IF(W5>=75,"Passed","Failed")) | Y5: =IF('TERM 1'!L11="","",'TERM 1'!L11) | Z5: =IF('TERM 2'!L11="","",'TERM 2'!L11) | AA5: =IF('TERM 3'!L11="","",'TERM 3'!L11) | AB5: =IF(COUNT(Y5:AA5)<3,"",ROUND(AVERAGE(Y5:AA5),0)) | AC5: =IF(AB5="","",IF(AB5>=75,"Passed","Failed")) | AD5: =IF('TERM 1'!M11="","",'TERM 1'!M11) | AE5: =IF('TERM 2'!M11="","",'TERM 2'!M11) | AF5: =IF('TERM 3'!M11="","",'TERM 3'!M11) | AG5: =IF(COUNT(AD5:AF5)<3,"",ROUND(AVERAGE(AD5:AF5),0)) | AH5: =IF(AG5="","",IF(AG5>=75,"Passed","Failed")) | AI5: =IF('TERM 1'!N11="","",'TERM 1'!N11) | AJ5: =IF('TERM 2'!N11="","",'TERM 2'!N11) | AK5: =IF('TERM 3'!N11="","",'TERM 3'!N11) | AL5: =IF(COUNT(AI5:AK5)<3,"",ROUND(AVERAGE(AI5:AK5),0)) | AM5: =IF(AL5="","",IF(AL5>=75,"Passed","Failed")) | AN5: =IF('TERM 1'!O11="","",'TERM 1'!O11) | AO5: =IF('TERM 2'!O11="","",'TERM 2'!O11) | AP5: =IF('TERM 3'!O11="","",'TERM 3'!O11) | AQ5: =IF(COUNT(AN5:AP5)<3,"",ROUND(AVERAGE(AN5:AP5),0)) | AR5: =IF(AQ5="","",IF(AQ5>=75,"Passed","Failed")) | AS5: =IF('TERM 1'!P11="","",'TERM 1'!P11) | AT5: =IF('TERM 2'!P11="","",'TERM 2'!P11) | AU5: =IF('TERM 3'!P11="","",'TERM 3'!P11) | AV5: =IF(COUNT(AS5:AU5)<3,"",ROUND(AVERAGE(AS5:AU5),0)) | AW5: =IF(AV5="","",IF(AV5>=75,"Passed","Failed")) | AX5: =IF('TERM 1'!S11="","",'TERM 1'!S11) | AY5: =IF('TERM 2'!S11="","",'TERM 2'!S11) | AZ5: =IF('TERM 3'!S11="","",'TERM 3'!S11) | BA5: =IF(COUNT(AX5:AZ5)<3,"",ROUND(AVERAGE(AX5:AZ5),0)) | BB5: =IF(BA5="","",IF(BA5>=75,"Passed","Failed")) | BC5: =IF('TERM 1'!Q11="","",'TERM 1'!Q11) | BD5: =IF('TERM 2'!Q11="","",'TERM 2'!Q11) | BE5: =IF('TERM 3'!Q11="","",'TERM 3'!Q11) | BF5: =IF(COUNT(BC5:BE5)<3,"",ROUND(AVERAGE(BC5:BE5),0)) | BG5: =IF(BF5="","",IF(BF5>=75,"Passed","Failed")) | BH5: =IF('TERM 1'!R11="","",'TERM 1'!R11) | BI5: =IF('TERM 2'!R11="","",'TERM 2'!R11) | BJ5: =IF('TERM 3'!R11="","",'TERM 3'!R11) | BK5: =IF(COUNT(BH5:BJ5)<3,"",ROUND(AVERAGE(BH5:BJ5),0)) | BL5: =IF(BK5="","",IF(BK5>=75,"Passed","Failed")) | BM5: =IF(COUNT(R5,W5,AB5,AG5,AL5,AQ5,AV5,BA5)<8,"",ROUND(AVERAGE(R5,W5,AB5,AG5,AL5,AQ5,AV5,BA5),0)) | BN5: =IF(BM5="","",IF(BM5>=75,"Passed","Failed"))
A6: =IF($K6="","",IF('INPUT DATA'!F5="","",'INPUT DATA'!F5)) | B6: =IF($K6="","",IF('INPUT DATA'!F6="","",'INPUT DATA'!F6)) | C6: =IF($K6="","",IF('INPUT DATA'!F8="","",'INPUT DATA'!F8)) | D6: =IF($K6="","",IF('INPUT DATA'!F7="","",'INPUT DATA'!F7)) | E6: =IF($K6="","",IF('INPUT DATA'!F11="","",'INPUT DATA'!F11)) | F6: =IF($K6="","",IF('INPUT DATA'!F13="","",'INPUT DATA'!F13)) | G6: =IF($K6="","",IF('INPUT DATA'!F21="","",'INPUT DATA'!F21)) | H6: =IF($K6="","",IF('INPUT DATA'!F22="","",'INPUT DATA'!F22)) | I6: =IF($K6="","",IF('INPUT DATA'!F23="","",'INPUT DATA'!F23)) | J6: =IF($K6="","",IF('INPUT DATA'!F14="","",'INPUT DATA'!F14)) | K6: =IF('INPUT DATA'!L10="","",'INPUT DATA'!L10) | L6: =IF('INPUT DATA'!M10="","",'INPUT DATA'!M10) | M6: =IF('TERM 1'!H12="","",'TERM 1'!H12) | N6: =IF(K6="","","M") | O6: =IF('TERM 1'!J12="","",'TERM 1'!J12) | P6: =IF('TERM 2'!J12="","",'TERM 2'!J12) | Q6: =IF('TERM 3'!J12="","",'TERM 3'!J12) | R6: =IF(COUNT(O6:Q6)<3,"",ROUND(AVERAGE(O6:Q6),0)) | S6: =IF(R6="","",IF(R6>=75,"Passed","Failed")) | T6: =IF('TERM 1'!K12="","",'TERM 1'!K12) | U6: =IF('TERM 2'!K12="","",'TERM 2'!K12) | V6: =IF('TERM 3'!K12="","",'TERM 3'!K12) | W6: =IF(COUNT(T6:V6)<3,"",ROUND(AVERAGE(T6:V6),0)) | X6: =IF(W6="","",IF(W6>=75,"Passed","Failed")) | Y6: =IF('TERM 1'!L12="","",'TERM 1'!L12) | Z6: =IF('TERM 2'!L12="","",'TERM 2'!L12) | AA6: =IF('TERM 3'!L12="","",'TERM 3'!L12) | AB6: =IF(COUNT(Y6:AA6)<3,"",ROUND(AVERAGE(Y6:AA6),0)) | AC6: =IF(AB6="","",IF(AB6>=75,"Passed","Failed")) | AD6: =IF('TERM 1'!M12="","",'TERM 1'!M12) | AE6: =IF('TERM 2'!M12="","",'TERM 2'!M12) | AF6: =IF('TERM 3'!M12="","",'TERM 3'!M12) | AG6: =IF(COUNT(AD6:AF6)<3,"",ROUND(AVERAGE(AD6:AF6),0)) | AH6: =IF(AG6="","",IF(AG6>=75,"Passed","Failed")) | AI6: =IF('TERM 1'!N12="","",'TERM 1'!N12) | AJ6: =IF('TERM 2'!N12="","",'TERM 2'!N12) | AK6: =IF('TERM 3'!N12="","",'TERM 3'!N12) | AL6: =IF(COUNT(AI6:AK6)<3,"",ROUND(AVERAGE(AI6:AK6),0)) | AM6: =IF(AL6="","",IF(AL6>=75,"Passed","Failed")) | AN6: =IF('TERM 1'!O12="","",'TERM 1'!O12) | AO6: =IF('TERM 2'!O12="","",'TERM 2'!O12) | AP6: =IF('TERM 3'!O12="","",'TERM 3'!O12) | AQ6: =IF(COUNT(AN6:AP6)<3,"",ROUND(AVERAGE(AN6:AP6),0)) | AR6: =IF(AQ6="","",IF(AQ6>=75,"Passed","Failed")) | AS6: =IF('TERM 1'!P12="","",'TERM 1'!P12) | AT6: =IF('TERM 2'!P12="","",'TERM 2'!P12) | AU6: =IF('TERM 3'!P12="","",'TERM 3'!P12) | AV6: =IF(COUNT(AS6:AU6)<3,"",ROUND(AVERAGE(AS6:AU6),0)) | AW6: =IF(AV6="","",IF(AV6>=75,"Passed","Failed")) | AX6: =IF('TERM 1'!S12="","",'TERM 1'!S12) | AY6: =IF('TERM 2'!S12="","",'TERM 2'!S12) | AZ6: =IF('TERM 3'!S12="","",'TERM 3'!S12) | BA6: =IF(COUNT(AX6:AZ6)<3,"",ROUND(AVERAGE(AX6:AZ6),0)) | BB6: =IF(BA6="","",IF(BA6>=75,"Passed","Failed")) | BC6: =IF('TERM 1'!Q12="","",'TERM 1'!Q12) | BD6: =IF('TERM 2'!Q12="","",'TERM 2'!Q12) | BE6: =IF('TERM 3'!Q12="","",'TERM 3'!Q12) | BF6: =IF(COUNT(BC6:BE6)<3,"",ROUND(AVERAGE(BC6:BE6),0)) | BG6: =IF(BF6="","",IF(BF6>=75,"Passed","Failed")) | BH6: =IF('TERM 1'!R12="","",'TERM 1'!R12) | BI6: =IF('TERM 2'!R12="","",'TERM 2'!R12) | BJ6: =IF('TERM 3'!R12="","",'TERM 3'!R12) | BK6: =IF(COUNT(BH6:BJ6)<3,"",ROUND(AVERAGE(BH6:BJ6),0)) | BL6: =IF(BK6="","",IF(BK6>=75,"Passed","Failed")) | BM6: =IF(COUNT(R6,W6,AB6,AG6,AL6,AQ6,AV6,BA6)<8,"",ROUND(AVERAGE(R6,W6,AB6,AG6,AL6,AQ6,AV6,BA6),0)) | BN6: =IF(BM6="","",IF(BM6>=75,"Passed","Failed"))
A7: =IF($K7="","",IF('INPUT DATA'!F5="","",'INPUT DATA'!F5)) | B7: =IF($K7="","",IF('INPUT DATA'!F6="","",'INPUT DATA'!F6)) | C7: =IF($K7="","",IF('INPUT DATA'!F8="","",'INPUT DATA'!F8)) | D7: =IF($K7="","",IF('INPUT DATA'!F7="","",'INPUT DATA'!F7)) | E7: =IF($K7="","",IF('INPUT DATA'!F11="","",'INPUT DATA'!F11)) | F7: =IF($K7="","",IF('INPUT DATA'!F13="","",'INPUT DATA'!F13)) | G7: =IF($K7="","",IF('INPUT DATA'!F21="","",'INPUT DATA'!F21)) | H7: =IF($K7="","",IF('INPUT DATA'!F22="","",'INPUT DATA'!F22)) | I7: =IF($K7="","",IF('INPUT DATA'!F23="","",'INPUT DATA'!F23)) | J7: =IF($K7="","",IF('INPUT DATA'!F14="","",'INPUT DATA'!F14)) | K7: =IF('INPUT DATA'!L11="","",'INPUT DATA'!L11) | L7: =IF('INPUT DATA'!M11="","",'INPUT DATA'!M11) | M7: =IF('TERM 1'!H13="","",'TERM 1'!H13) | N7: =IF(K7="","","M") | O7: =IF('TERM 1'!J13="","",'TERM 1'!J13) | P7: =IF('TERM 2'!J13="","",'TERM 2'!J13) | Q7: =IF('TERM 3'!J13="","",'TERM 3'!J13) | R7: =IF(COUNT(O7:Q7)<3,"",ROUND(AVERAGE(O7:Q7),0)) | S7: =IF(R7="","",IF(R7>=75,"Passed","Failed")) | T7: =IF('TERM 1'!K13="","",'TERM 1'!K13) | U7: =IF('TERM 2'!K13="","",'TERM 2'!K13) | V7: =IF('TERM 3'!K13="","",'TERM 3'!K13) | W7: =IF(COUNT(T7:V7)<3,"",ROUND(AVERAGE(T7:V7),0)) | X7: =IF(W7="","",IF(W7>=75,"Passed","Failed")) | Y7: =IF('TERM 1'!L13="","",'TERM 1'!L13) | Z7: =IF('TERM 2'!L13="","",'TERM 2'!L13) | AA7: =IF('TERM 3'!L13="","",'TERM 3'!L13) | AB7: =IF(COUNT(Y7:AA7)<3,"",ROUND(AVERAGE(Y7:AA7),0)) | AC7: =IF(AB7="","",IF(AB7>=75,"Passed","Failed")) | AD7: =IF('TERM 1'!M13="","",'TERM 1'!M13) | AE7: =IF('TERM 2'!M13="","",'TERM 2'!M13) | AF7: =IF('TERM 3'!M13="","",'TERM 3'!M13) | AG7: =IF(COUNT(AD7:AF7)<3,"",ROUND(AVERAGE(AD7:AF7),0)) | AH7: =IF(AG7="","",IF(AG7>=75,"Passed","Failed")) | AI7: =IF('TERM 1'!N13="","",'TERM 1'!N13) | AJ7: =IF('TERM 2'!N13="","",'TERM 2'!N13) | AK7: =IF('TERM 3'!N13="","",'TERM 3'!N13) | AL7: =IF(COUNT(AI7:AK7)<3,"",ROUND(AVERAGE(AI7:AK7),0)) | AM7: =IF(AL7="","",IF(AL7>=75,"Passed","Failed")) | AN7: =IF('TERM 1'!O13="","",'TERM 1'!O13) | AO7: =IF('TERM 2'!O13="","",'TERM 2'!O13) | AP7: =IF('TERM 3'!O13="","",'TERM 3'!O13) | AQ7: =IF(COUNT(AN7:AP7)<3,"",ROUND(AVERAGE(AN7:AP7),0)) | AR7: =IF(AQ7="","",IF(AQ7>=75,"Passed","Failed")) | AS7: =IF('TERM 1'!P13="","",'TERM 1'!P13) | AT7: =IF('TERM 2'!P13="","",'TERM 2'!P13) | AU7: =IF('TERM 3'!P13="","",'TERM 3'!P13) | AV7: =IF(COUNT(AS7:AU7)<3,"",ROUND(AVERAGE(AS7:AU7),0)) | AW7: =IF(AV7="","",IF(AV7>=75,"Passed","Failed")) | AX7: =IF('TERM 1'!S13="","",'TERM 1'!S13) | AY7: =IF('TERM 2'!S13="","",'TERM 2'!S13) | AZ7: =IF('TERM 3'!S13="","",'TERM 3'!S13) | BA7: =IF(COUNT(AX7:AZ7)<3,"",ROUND(AVERAGE(AX7:AZ7),0)) | BB7: =IF(BA7="","",IF(BA7>=75,"Passed","Failed")) | BC7: =IF('TERM 1'!Q13="","",'TERM 1'!Q13) | BD7: =IF('TERM 2'!Q13="","",'TERM 2'!Q13) | BE7: =IF('TERM 3'!Q13="","",'TERM 3'!Q13) | BF7: =IF(COUNT(BC7:BE7)<3,"",ROUND(AVERAGE(BC7:BE7),0)) | BG7: =IF(BF7="","",IF(BF7>=75,"Passed","Failed")) | BH7: =IF('TERM 1'!R13="","",'TERM 1'!R13) | BI7: =IF('TERM 2'!R13="","",'TERM 2'!R13) | BJ7: =IF('TERM 3'!R13="","",'TERM 3'!R13) | BK7: =IF(COUNT(BH7:BJ7)<3,"",ROUND(AVERAGE(BH7:BJ7),0)) | BL7: =IF(BK7="","",IF(BK7>=75,"Passed","Failed")) | BM7: =IF(COUNT(R7,W7,AB7,AG7,AL7,AQ7,AV7,BA7)<8,"",ROUND(AVERAGE(R7,W7,AB7,AG7,AL7,AQ7,AV7,BA7),0)) | BN7: =IF(BM7="","",IF(BM7>=75,"Passed","Failed"))
